Workbook

Sheet 豆单_零售（2602)
B2: 订购前请先看以下说明 单品豆规格皆为200克装 配方型/意式豆皆为500克装 低单价咖啡通常会有常备库存，7天内烘焙的库存会直接出货 ＊下单后三工作日内烘焙发货（周末休息）
B3: ＊付款请支付下方三个公司户收款方式，不用个人微信收款~敬请见谅＊
B4: 折石咖啡 江承哲严选咖啡豆单
B5: 产区 | C5: 序号 | D5: 烘焙度 | E5: 规格 | F5: 香型 | G5: 果酸感 | H5: 简称 | I5: 咖啡/商品名称 | J5: 享味价
B6: 非洲 | C6: 1 | D6: 中浅焙 | E6: 200克 | F6: 清新 果香 | G6: ♤♤♤♤ | H6: 柠檬花 | I6: ★★★（经典畅销）埃塞俄比亚耶加雪菲柠檬花 #清香柠檬花 #蜂蜜红茶 #轻焦糖 #甜酸明亮愉悦 | J6: 66
C7: 2 | D7: 中焙 | E7: 200克 | F7: 蜜香红茶 柑橘甜 | G7: ♤♤ | H7: 蜜香摩卡 | I7: 埃塞俄比亚耶加雪菲蜜香摩卡 #蜂蜜 #柑橘 #锡兰红茶 #淡花香 #甜美温和口感舒爽有厚度 | J7: 66
C8: 3 | D8: 深焙 | E8: 200克 | F8: 厚重 浓香 | G8: ♤ | H8: 黑美人 | I8: 埃塞俄比亚耶加雪菲摩卡黑美人（深烘焙精品咖啡的典范） #焦糖烤橘子 #可可 #豆蔻 #甘甜醇香 | J8: 66
C9: 4 | D9: 中浅焙 | E9: 200克 | F9: 花韵 果香 | G9: ♤♤♤♤ | H9: 塔拉图 | I9: ★★埃塞俄比亚耶加雪菲班科塔拉图G1双重厌氧水洗 （中国之选铂金奖，相当好喝） #高级橙花 #柠檬 #棉花糖 #红布林 | J9: 118
C10: 5 | D10: 中浅焙 | E10: 200克 | F10: 花韵 果香 | G10: ♤♤♤♤ | H10: 花魁XS | I10: 埃塞俄比亚谷吉汉贝拉正宗2025花魁XS限量版 #紫葡萄 #蓝莓 #草莓水果糖 #香水月季 #高甜丰厚的果汁感 | J10: 118
C11: 6 | D11: 中浅焙 | E11: 200克 | F11: 优雅 果香 | G11: ♤♤♤♤ | H11: 赤拉客厌氧 | I11: 埃塞俄比亚班莎ALO赤拉客厌G1厌氧日晒 #蓝莓 #树莓 #柑橘 #花香 #黄桃般丰厚略有粘度的好口感 | J11: 118
C12: 7 | D12: 中浅焙 | E12: 200克 | F12: 优雅 果香 | G12: ♤♤♤♤ | H12: 桃可可 | I12: ★★埃塞俄比亚希达摩桃可可G1日晒 #草莓 #水蜜桃 #蓝莓 #巨峰葡萄 #风味饱满、多汁甜美 | J12: 118
C13: 8 | D13: 中浅焙 | E13: 200克 | F13: 莓果花香 | G13: ♤♤♤♤ | H13: 肯尼亚紫花 | I13: 肯尼亚基隆贝紫花SL28 （AA TOP规格） #紫色花香#鲜蓝莓#西梅#柑橘,丰富甜美独到浓香 | J13: 168
C14: 9 | D14: 中浅焙 | E14: 200克 | F14: 莓果花香 | G14: ♤♤♤♤ | H14: 莓宴 | I14: 肯尼亚奇安布奥克兰庄园-莓宴（AA TOP规格） #黑莓 #蓝莓 #覆盆子 #苹果花 #血橙 #果汁感强，酸甜愉悦又饱满 | J14: 110
C15: 10 | D15: 中浅焙 | E15: 200克 | F15: 莓果花香 | G15: ♤♤♤♤ | H15: 乌克栗栗 | I15: ★★肯尼亚乌克栗栗/黑莓皇后（AA TOP规格） #黑醋栗 #黑莓 #乌梅 #口感浑厚、风味强劲扎实 | J15: 128
C16: 11 | D16: 中焙 | E16: 200克 | F16: 莓果蜜李 甜润厚香 | G16: ♤♤ | H16: 第七图 | I16: ★埃塞俄比亚罕贝拉第七图日晒 #蓝莓 #西梅 #油桃 #甜蜜李 #尾韵具有玫瑰李和腰果一样的温润回味，口感厚实甜度高 | J16: 98
C17: 12 | D17: 中深焙 | E17: 200克 | F17: 醇甜厚实 巧克力浓香 | G17: ♤ | H17: 蜜可可 | I17: 肯尼亚尼耶利蜜可可Mielcoco（饱饱的厚甜感又顺滑哦） #巧克力 #锡兰红茶 #小白杏 #柴烧黑糖 顺滑厚实甜美 | J17: 75
B18: 中 南 美 洲 | C18: 13 | D18: 中浅焙 | E18: 200克 | F18: 特色香草植物 发酵果香 | G18: ♤♤♤♤ | H18: 愉悦Wush Wush | I18: 哥伦比亚金迪奥愉悦庄园黑蜜条纹橙Wush Wush #烤红椒 #柠檬草 #花香 #风味独特强劲，特色鲜明 | J18: 168
C19: 14 | D19: 中浅焙 | E19: 200克 | F19: 特色清酒香 | G19: ♤♤♤♤ | H19: 天堂92条纹波旁 | I19: ★★★★★哥伦比亚考卡天堂92日本清酒曲厌氧水洗条纹波旁 #清酒 #粉色花香 #荔枝 #口感活泼余韵悠长 | J19: 368
C20: 15 | D20: 中浅焙 | E20: 200克 | F20: 多层次 果香酒韵 | G20: ♤♤ | H20: 天堂92朗姆酒 | I20: ★★★★★哥伦比亚考卡天堂92啤酒酵母+朗姆酒桶静置（焙度加深！更加厚重好喝） #黑朗姆酒 #焦糖巧克力 #啤酒花 #层次多元口感爽口厚重 | J20: 208
C21: 16 | D21: 中浅焙 | E21: 200克 | F21: 高浓度多层次 莓果水果浓香 | G21: ♤♤♤♤ | H21: 分界线庄园希爪 | I21: ★★★★哥伦比亚分界线庄园双重发酵日晒希爪Sidra（好喝到炸裂！浓郁复合果汁） #复合莓果汁 #杏桃 #紫色水果 #紫色花香 #口感质地细腻饱满甜美 | J21: 358
C22: 17 | D22: 中浅焙 | E22: 200克 | F22: 浓郁 果干爆香 | G22: ♤♤♤♤ | H22: 90+埃莱塔瑰夏 | I22: ★★★★★巴拿马沃肯90+ Eleta埃莱塔瑰夏特殊处理法（高端品牌风味强度就是高） #蜜渍凤梨 #佛手柑 #柚子 #口感丰富酸甜活泼 | J22: 380
C23: 18 | D23: 中浅焙 | E23: 200克 | F23: 高雅 花果香 | G23: ♤♤♤♤ | H23: 翡翠绿标 哈拉米约 | I23: ★★★★巴拿马波奎特翡翠庄园绿标水洗瑰夏哈拉米约地块 #香草玫瑰 #柠檬 #黑莓 #复合水果茶 #活泼多汁口感 | J23: 550
C24: 19 | D24: 中浅焙 | E24: 200克 | F24: 丝绒莓果韵 | G24: ♤♤♤♤ | H24: 黛博拉瑰夏 | I24: ★★★★巴拿马沃坎黛博拉庄园“星空”瑰夏 酵母发酵日晒（世界冠军级庄园，层次繁复且极具张力） #奶油草莓 #桑葚 #山楂葡萄干 #口感丝滑甜感炸裂 | J24: 980
C25: 20 | D25: 中浅焙 | E25: 200克 | F25: 馥郁蜜渍 花果香 | G25: ♤♤♤♤ | H25: 艾力达瑰夏 | I25: ★★★★巴拿马艾力达庄园·鳄梨地块 瑰夏 ASD暗室干燥日晒（BOP竞标传奇名园，极致浓缩的果香盛宴） #馥郁花香 #多汁油桃 #清甜砂糖橘 #如热带果汁般鲜甜 | J25: 980
C26: 21 | D26: 中焙 | E26: 200克 | F26: 蜜糖甜李花香 | G26: ♤♤ | H26: 分界线瑰夏 | I26: ★★★★哥伦比亚分界线庄园水洗瑰夏（名庄瑰夏，性价比高！） #蜂糖李 #槐花蜜 #鲜炒绿茶尾韵 #口感甜厚圆润愉悦 | J26: 240
C27: 22 | D27: 中焙 | E27: 200克 | F27: 圆润 果香 | G27: ♤♤ | H27: 蓝山 | I27: 牙买加蓝山一号铁比卡（正宗蓝山中的优质货，送礼好选） #蜜糖杏李 #高质感巧克力 #甜榛子 #丝滑平衡无敌的口感 | J27: 430
B28: 亚洲 | C28: 23 | D28: 中焙 | E28: 200克 | F28: 高浓度多层次 莓果水果浓香 | G28: ♤♤ | H28: DR132 | I28: 西双版纳孟宋高海拔新品种DR132厌氧日晒(稀有!黄果皮变种卡蒂姆） #青芒 #生姜花 #肉豆蔻 #糖蜜与热带水果甜 | J28: 98
C29: 24 | D29: 中焙 | E29: 200克 | F29: 坚果糖蜜 | G29: ♤♤♤ | H29: 云佳蜜 | I29: 云南临沧云佳庄园日晒云佳蜜（临沧精品咖啡协会会长稳定生产口粮级别好豆！） #巴旦木 #糖蜜 #轻发酵果干 | J29: 66
C30: 25 | D30: 中焙 | E30: 200克 | F30: 高雅 蜜甜核果香 | G30: ♤♤♤ | H30: 太阳鸟 | I30: 西双版纳西定云乐庄园高海拔水洗巴蒂安Batian巴天太阳鸟（稀有品种，高质感） #蔓越莓 #柑橘 #玫瑰李 #高活泼酸甜醇厚咖啡 | J30: 168
C31: 26 | D31: 中深焙 | E31: 200克 | F31: 浓香 | G31: ♤♤ | H31: 日光曼特宁 | I31: ★苏门答腊日光曼特宁(经典曼特宁的甜香风格) #森林气息 #焦糖 #坚果黑可可 | J31: 78
C32: 27 | D32: 中深焙 | E32: 200克 | F32: 浓香 | G32: ♤♤ | H32: 白金曼特宁 | I32: ★★苏门答腊迦幼山白金曼特宁水洗处理法（颗粒又大又长，十分漂亮） #仙草 #糖蜜 #黑巧克力 #黑李甜酸 #质感厚重却十足干净 | J32: 98
C33: 28 | D33: 中深焙 | E33: 200克 | F33: 浓香 | G33: ♤♤ | H33: 林东之星 | I33: ★★★★苏门答腊多巴湖林东之星（风味深沉内敛，拥有曼特宁中少见的极高净度） #雪松木 #回甘草本 #黑巧克力 #西柚微酸 #口感如糖浆般粘稠 | J33: 118
C34: 29 | D34: 中焙 | E34: 200克 | F34: 圆润 果香 | G34: ♤♤ | H34: 兰特卡鲁瓦 | I34: 苏拉威西托拉贾兰特卡鲁瓦日晒 #苹果 #樱桃 #核果 #柠檬草 #温润口感顺滑浑厚 | J34: 118
B35: 折石 配方 咖啡 （意式） | C35: 30 | D35: 深焙 | E35: 500克 | F35: 威力 浓香 | G35: ♤ | H35: 黑洞 | I35: ★★无负担配方设计 黑洞/500克装（经典产品，推荐咖啡店意式市使用首选） （孟连+普洱+哥伦比亚+西达摩） #厚重苦甜巧克力 #核果甜香 #重焦糖 #饱满却不苦涩，奶咖的绝配 | J35: 110
C36: 31 | D36: 中深焙 | E36: 500克 | F36: 圆润 坚果与果香 | G36: ♤♤ | H36: 流星 | I36: ★★无负担配方设计 流星/500克装（经典产品，咖啡店首选）（孟连+普洱+西达摩） #锡兰红茶 #甜杏李 #坚果 #口感温润，轻盈柔顺不迟腻 | J36: 110
C37: 32 | D37: 中焙 | E37: 500克 | F37: 圆润 果香与甜香 | G37: ♤♤ | H37: 天之语 | I37: 细腻感配方设计 天之语 500克装（埃塞水洗&日晒+巴西+哥伦比亚） #红糖蜜 #烤橘香 #奶油巧克力 #柔顺干净追求平衡的典范口感 | J37: 120
C38: 33 | D38: 中浅焙 | E38: 500克 | F38: 多层次 花果香 | G38: ♤♤♤ | H38: 花宙2.0 | I38: ★★细腻感配方设计 花宙2.0甜美式配方（埃塞日晒+肯尼亚+哥伦比亚+耶加） #甜柑橘 #鲜红莓 #核果蜜香 #清爽上扬果汁感甜酸质地 | J38: 125
C39: 34 | D39: 深焙 | E39: 500克 | F39: 厚重 多层次浓香 | G39: ♤ | H39: 充电桩 | I39: ★★★★盲盒配方 充电桩/500克装（主基调一致 每批次细节不同，重口味者的心头好） #巧克力 #重焦糖 #朗姆威士忌 #入口丰富 #口感饱满尾韵层次 | J39: 110
B41: ★热门推荐
B42: ★★ 强力推荐
...

Sheet 豆单_批发（2602) 
B2: 订购前请先看以下说明 单品豆规格皆为200克装，大量订购优惠的[200克]24包是针对单品豆的批发条件 意式豆皆为500克装，大量订购优惠的[500克]32包是针对意式豆的批发条件 咖啡豆需要满足单一品项的数量才能获得该品项的优惠价 ＊咖啡通常会有常备库存，7天内烘焙的库存会直接出货 ＊下单后三工作日内烘焙发货（周末休息） ＊ 商户合作优惠优惠无最低起订量，但您若能尽量单品豆以4包倍数订购，意式豆以2包500克为单位订购，我们将无比感谢您 ＊ 合作商户享大量订购优惠价，意式豆请按32包倍数订购，单品豆按24包倍数订购 ＊ 大量订购我们能够用上大机器烘焙，将省下来的时间回馈给您，有能力可以多订一些，更加优惠哦
B3: ＊付款请支付下方三个公司户收款方式，不用个人微信收款~敬请见谅＊
B4: 折石咖啡 江承哲严选咖啡豆单
B5: 产区 | C5: 序号 | D5: 烘焙度 | E5: 规格 | F5: 香型 | G5: 果酸感 | H5: 简称 | I5: 咖啡/商品名称 | J5: 享味价 | K5: 商户合作优惠 [200克]4包/件 [500克]2包/件 | L5: 大量订购优惠 [200克]24包 [500克]32包 | M5: 超大量优惠 [200克]60包 [500克]96包
B6: 非洲 | C6: 1 | D6: 中浅焙 | E6: 200克 | F6: 清新 果香 | G6: ♤♤♤♤ | H6: 柠檬花 | I6: ★★★（经典畅销）埃塞俄比亚耶加雪菲柠檬花 #清香柠檬花 #蜂蜜红茶 #轻焦糖 #甜酸明亮愉悦 | J6: 66 | K6: 50 | L6: 46 | M6: 40
C7: 2 | D7: 中焙 | E7: 200克 | F7: 蜜香红茶 柑橘甜 | G7: ♤♤ | H7: 蜜香摩卡 | I7: 埃塞俄比亚耶加雪菲蜜香摩卡 #蜂蜜 #柑橘 #锡兰红茶 #淡花香 #甜美温和口感舒爽有厚度 | J7: 66 | K7: 50 | L7: 46 | M7: 40
C8: 3 | D8: 深焙 | E8: 200克 | F8: 厚重 浓香 | G8: ♤ | H8: 黑美人 | I8: 埃塞俄比亚耶加雪菲摩卡黑美人（深烘焙精品咖啡的典范） #焦糖烤橘子 #可可 #豆蔻 #甘甜醇香 | J8: 66 | K8: 50 | L8: 46 | M8: 40
C9: 4 | D9: 中浅焙 | E9: 200克 | F9: 花韵 果香 | G9: ♤♤♤♤ | H9: 塔拉图 | I9: ★★埃塞俄比亚耶加雪菲班科塔拉图G1双重厌氧水洗 （中国之选铂金奖，相当好喝） #高级橙花 #柠檬 #棉花糖 #红布林 | J9: 118 | K9: 88 | L9: 82 | M9: 72
C10: 5 | D10: 中浅焙 | E10: 200克 | F10: 花韵 果香 | G10: ♤♤♤♤ | H10: 花魁XS | I10: 埃塞俄比亚谷吉汉贝拉正宗2025花魁XS限量版 #紫葡萄 #蓝莓 #草莓水果糖 #香水月季 #高甜丰厚的果汁感 | J10: 118 | K10: 88 | L10: 82 | M10: 72
C11: 6 | D11: 中浅焙 | E11: 200克 | F11: 优雅 果香 | G11: ♤♤♤♤ | H11: 赤拉客厌氧 | I11: 埃塞俄比亚班莎ALO赤拉客厌G1厌氧日晒 #蓝莓 #树莓 #柑橘 #花香 #黄桃般丰厚略有粘度的好口感 | J11: 118 | K11: 88 | L11: 82 | M11: 72
C12: 7 | D12: 中浅焙 | E12: 200克 | F12: 优雅 果香 | G12: ♤♤♤♤ | H12: 桃可可 | I12: ★★埃塞俄比亚希达摩桃可可G1日晒 #草莓 #水蜜桃 #蓝莓 #巨峰葡萄 #风味饱满、多汁甜美 | J12: 118 | K12: 88 | L12: 82 | M12: 72
C13: 8 | D13: 中浅焙 | E13: 200克 | F13: 莓果花香 | G13: ♤♤♤♤ | H13: 肯尼亚紫花 | I13: 肯尼亚基隆贝紫花SL28 （AA TOP规格） #紫色花香#鲜蓝莓#西梅#柑橘,丰富甜美独到浓香 | J13: 168 | K13: =J13*0.7 -> 117.6 | L13: 100 | M13: =J13*0.5 -> 84
C14: 9 | D14: 中浅焙 | E14: 200克 | F14: 莓果花香 | G14: ♤♤♤♤ | H14: 莓宴 | I14: 肯尼亚奇安布奥克兰庄园-莓宴（AA TOP规格） #黑莓 #蓝莓 #覆盆子 #苹果花 #血橙 #果汁感强，酸甜愉悦又饱满 | J14: 110 | K14: =J14*0.7 -> 77 | L14: 72 | M14: 66
C15: 10 | D15: 中浅焙 | E15: 200克 | F15: 莓果花香 | G15: ♤♤♤♤ | H15: 乌克栗栗 | I15: ★★肯尼亚乌克栗栗/黑莓皇后（AA TOP规格） #黑醋栗 #黑莓 #乌梅 #口感浑厚、风味强劲扎实 | J15: 128 | K15: =J15*0.7 -> 89.6 | L15: 72 | M15: 66
C16: 11 | D16: 中焙 | E16: 200克 | F16: 莓果蜜李 甜润厚香 | G16: ♤♤ | H16: 第七图 | I16: ★埃塞俄比亚罕贝拉第七图日晒 #蓝莓 #西梅 #油桃 #甜蜜李 #尾韵具有玫瑰李和腰果一样的温润回味，口感厚实甜度高 | J16: 98 | K16: 75 | L16: 68 | M16: 60
C17: 12 | D17: 中深焙 | E17: 200克 | F17: 醇甜厚实 巧克力浓香 | G17: ♤ | H17: 蜜可可 | I17: 肯尼亚尼耶利蜜可可Mielcoco（饱饱的厚甜感又顺滑哦） #巧克力 #锡兰红茶 #小白杏 #柴烧黑糖 顺滑厚实甜美 | J17: 75 | K17: 55 | L17: 49 | M17: 45
B18: 中 南 美 洲 | C18: 13 | D18: 中浅焙 | E18: 200克 | F18: 特色香草植物 发酵果香 | G18: ♤♤♤♤ | H18: 愉悦Wush Wush | I18: 哥伦比亚金迪奥愉悦庄园黑蜜条纹橙Wush Wush #烤红椒 #柠檬草 #花香 #风味独特强劲，特色鲜明 | J18: 168 | K18: 118 | L18: 100 | M18: 84
C19: 14 | D19: 中浅焙 | E19: 200克 | F19: 特色清酒香 | G19: ♤♤♤♤ | H19: 天堂92条纹波旁 | I19: ★★★★★哥伦比亚考卡天堂92日本清酒曲厌氧水洗条纹波旁 #清酒 #粉色花香 #荔枝 #口感活泼余韵悠长 | J19: 368 | K19: 221 | L19: 177 | M19: 148
C20: 15 | D20: 中浅焙 | E20: 200克 | F20: 多层次 果香酒韵 | G20: ♤♤ | H20: 天堂92朗姆酒 | I20: ★★★★★哥伦比亚考卡天堂92啤酒酵母+朗姆酒桶静置（焙度加深！更加厚重好喝） #黑朗姆酒 #焦糖巧克力 #啤酒花 #层次多元口感爽口厚重 | J20: 208 | K20: 126 | L20: 118 | M20: 109
C21: 16 | D21: 中浅焙 | E21: 200克 | F21: 高浓度多层次 莓果水果浓香 | G21: ♤♤♤♤ | H21: 分界线庄园希爪 | I21: ★★★★哥伦比亚分界线庄园双重发酵日晒希爪Sidra（好喝到炸裂！浓郁复合果汁） #复合莓果汁 #杏桃 #紫色水果 #紫色花香 #口感质地细腻饱满甜美 | J21: 358 | K21: =J21*0.75 -> 268.5 | L21: 215 | M21: 179
C22: 17 | D22: 中浅焙 | E22: 200克 | F22: 浓郁 果干爆香 | G22: ♤♤♤♤ | H22: 90+埃莱塔瑰夏 | I22: ★★★★★巴拿马沃肯90+ Eleta埃莱塔瑰夏特殊处理法（高端品牌风味强度就是高） #蜜渍凤梨 #佛手柑 #柚子 #口感丰富酸甜活泼 | J22: 380 | K22: 225 | L22: 212 | M22: 200
C23: 18 | D23: 中浅焙 | E23: 200克 | F23: 高雅 花果香 | G23: ♤♤♤♤ | H23: 翡翠绿标 哈拉米约 | I23: ★★★★巴拿马波奎特翡翠庄园绿标水洗瑰夏哈拉米约地块 #香草玫瑰 #柠檬 #黑莓 #复合水果茶 #活泼多汁口感 | J23: 550 | K23: 480 | L23: 336 | M23: 330
C24: 19 | D24: 中浅焙 | E24: 200克 | F24: 丝绒莓果韵 | G24: ♤♤♤♤ | H24: 黛博拉瑰夏 | I24: ★★★★巴拿马沃坎黛博拉庄园“星空”瑰夏 酵母发酵日晒（世界冠军级庄园，层次繁复且极具张力） #奶油草莓 #桑葚 #山楂葡萄干 #口感丝滑甜感炸裂 | J24: 980 | K24: 850 | L24: 686 | M24: 598
C25: 20 | D25: 中浅焙 | E25: 200克 | F25: 馥郁蜜渍 花果香 | G25: ♤♤♤♤ | H25: 艾力达瑰夏 | I25: ★★★★巴拿马艾力达庄园·鳄梨地块 瑰夏 ASD暗室干燥日晒（BOP竞标传奇名园，极致浓缩的果香盛宴） #馥郁花香 #多汁油桃 #清甜砂糖橘 #如热带果汁般鲜甜 | J25: 980 | K25: 850 | L25: 686 | M25: 598
C26: 21 | D26: 中焙 | E26: 200克 | F26: 蜜糖甜李花香 | G26: ♤♤ | H26: 分界线瑰夏 | I26: ★★★★哥伦比亚分界线庄园水洗瑰夏（名庄瑰夏，性价比高！） #蜂糖李 #槐花蜜 #鲜炒绿茶尾韵 #口感甜厚圆润愉悦 | J26: 240 | K26: 180 | L26: 170 | M26: 160
C27: 22 | D27: 中焙 | E27: 200克 | F27: 圆润 果香 | G27: ♤♤ | H27: 蓝山 | I27: 牙买加蓝山一号铁比卡（正宗蓝山中的优质货，送礼好选） #蜜糖杏李 #高质感巧克力 #甜榛子 #丝滑平衡无敌的口感 | J27: 430 | K27: 300 | L27: 258 | M27: 215
B28: 亚洲 | C28: 23 | D28: 中焙 | E28: 200克 | F28: 高浓度多层次 莓果水果浓香 | G28: ♤♤ | H28: DR132 | I28: 西双版纳孟宋高海拔新品种DR132厌氧日晒(稀有!黄果皮变种卡蒂姆） #青芒 #生姜花 #肉豆蔻 #糖蜜与热带水果甜 | J28: 98 | K28: 75 | L28: 70 | M28: 65
C29: 24 | D29: 中焙 | E29: 200克 | F29: 坚果糖蜜 | G29: ♤♤♤ | H29: 云佳蜜 | I29: 云南临沧云佳庄园日晒云佳蜜（临沧精品咖啡协会会长稳定生产口粮级别好豆！） #巴旦木 #糖蜜 #轻发酵果干 | J29: 66 | K29: 50 | L29: 46 | M29: 50
C30: 25 | D30: 中焙 | E30: 200克 | F30: 高雅 蜜甜核果香 | G30: ♤♤♤ | H30: 太阳鸟 | I30: 西双版纳西定云乐庄园高海拔水洗巴蒂安Batian巴天太阳鸟（稀有品种，高质感） #蔓越莓 #柑橘 #玫瑰李 #高活泼酸甜醇厚咖啡 | J30: 168 | K30: 126 | L30: 118 | M30: 109
C31: 26 | D31: 中深焙 | E31: 200克 | F31: 浓香 | G31: ♤♤ | H31: 日光曼特宁 | I31: ★苏门答腊日光曼特宁(经典曼特宁的甜香风格) #森林气息 #焦糖 #坚果黑可可 | J31: 78 | K31: 60 | L31: 55 | M31: 50
C32: 27 | D32: 中深焙 | E32: 200克 | F32: 浓香 | G32: ♤♤ | H32: 白金曼特宁 | I32: ★★苏门答腊迦幼山白金曼特宁水洗处理法（颗粒又大又长，十分漂亮） #仙草 #糖蜜 #黑巧克力 #黑李甜酸 #质感厚重却十足干净 | J32: 98 | K32: 75 | L32: 70 | M32: 65
C33: 28 | D33: 中深焙 | E33: 200克 | F33: 浓香 | G33: ♤♤ | H33: 林东之星 | I33: ★★★★苏门答腊多巴湖林东之星（风味深沉内敛，拥有曼特宁中少见的极高净度） #雪松木 #回甘草本 #黑巧克力 #西柚微酸 #口感如糖浆般粘稠 | J33: 118 | K33: 88 | L33: 82 | M33: 72
C34: 29 | D34: 中焙 | E34: 200克 | F34: 圆润 果香 | G34: ♤♤ | H34: 兰特卡鲁瓦 | I34: 苏拉威西托拉贾兰特卡鲁瓦日晒 #苹果 #樱桃 #核果 #柠檬草 #温润口感顺滑浑厚 | J34: 118 | K34: 88 | L34: 82 | M34: 72
B35: 折石 配方 咖啡 （意式） | C35: 30 | D35: 深焙 | E35: 500克 | F35: 威力 浓香 | G35: ♤ | H35: 黑洞 | I35: ★★无负担配方设计 黑洞/500克装（经典产品，推荐咖啡店意式市使用首选） （孟连+普洱+哥伦比亚+西达摩） #厚重苦甜巧克力 #核果甜香 #重焦糖 #饱满却不苦涩，奶咖的绝配 | J35: 110 | K35: 80 | L35: 70 | M35: 65
C36: 31 | D36: 中深焙 | E36: 500克 | F36: 圆润 坚果与果香 | G36: ♤♤ | H36: 流星 | I36: ★★无负担配方设计 流星/500克装（经典产品，咖啡店首选）（孟连+普洱+西达摩） #锡兰红茶 #甜杏李 #坚果 #口感温润，轻盈柔顺不迟腻 | J36: 110 | K36: 80 | L36: 70 | M36: 65
C37: 32 | D37: 中焙 | E37: 500克 | F37: 圆润 果香与甜香 | G37: ♤♤ | H37: 天之语 | I37: 细腻感配方设计 天之语 500克装（埃塞水洗&日晒+巴西+哥伦比亚） #红糖蜜 #烤橘香 #奶油巧克力 #柔顺干净追求平衡的典范口感 | J37: 120 | K37: 90 | L37: 80 | M37: 75
C38: 33 | D38: 中浅焙 | E38: 500克 | F38: 多层次 花果香 | G38: ♤♤♤ | H38: 花宙2.0 | I38: ★★细腻感配方设计 花宙2.0甜美式配方（埃塞日晒+肯尼亚+哥伦比亚+耶加） #甜柑橘 #鲜红莓 #核果蜜香 #清爽上扬果汁感甜酸质地 | J38: 125 | K38: 95 | L38: 85 | M38: 80
C39: 34 | D39: 深焙 | E39: 500克 | F39: 厚重 多层次浓香 | G39: ♤ | H39: 充电桩 | I39: ★★★★盲盒配方 充电桩/500克装（主基调一致 每批次细节不同，重口味者的心头好） #巧克力 #重焦糖 #朗姆威士忌 #入口丰富 #口感饱满尾韵层次 | J39: 110 | K39: 80 | L39: 70 | M39: 65
B40: 以上商户合作优惠价与大量订购批发价含税不含运
H41: 扫描付款方式
...

Sheet 豆单_零售（2511)
B2: 订购前请先看以下说明 单品豆规格皆为200克装 配方型/意式豆皆为500克装 低单价咖啡通常会有常备库存，7天内烘焙的库存会直接出货 ＊下单后三工作日内烘焙发货（周末休息）
B3: ＊付款请支付下方三个公司户收款方式，不用个人微信收款~敬请见谅＊
B4: 折石咖啡 江承哲严选咖啡豆单
B5: 产区 | C5: 序号 | D5: 烘焙度 | E5: 规格 | F5: 香型 | G5: 果酸感 | H5: 简称 | I5: 咖啡/商品名称 | J5: 享味价
B6: 非洲 | C6: 1 | D6: 中浅焙 | E6: 200克 | F6: 清新 果香 | G6: ♤♤♤♤ | H6: 柠檬花 | I6: ☆★★（经典畅销）埃塞俄比亚耶加雪菲柠檬花 （新产季好喝耶） #清香柠檬花 #蜂蜜红茶 #轻焦糖 #甜酸明亮愉悦 | J6: 66
C7: 2 | D7: 中焙 | E7: 200克 | F7: 蜜香红茶 柑橘甜 | G7: ♤♤ | H7: 蜜香摩卡 | I7: 埃塞俄比亚耶加雪菲蜜香摩卡 #蜂蜜 #柑橘 #锡兰红茶 #淡花香 #甜美温和口感舒爽有厚度 | J7: 66
C8: 3 | D8: 深焙 | E8: 200克 | F8: 厚重 浓香 | G8: ♤ | H8: 黑美人 | I8: 埃塞俄比亚耶加雪菲摩卡黑美人（深烘焙精品咖啡的典范） #焦糖烤橘子 #可可 #豆蔻 #甘甜醇香 | J8: 66
C9: 4 | D9: 中浅焙 | E9: 200克 | F9: 花韵 果香 | G9: ♤♤♤♤ | H9: 塔拉图 | I9: 埃塞俄比亚耶加雪菲班科塔拉图G1双重厌氧水洗 （中国之选铂金奖，相当好喝） #高级橙花 #柠檬 #棉花糖 #红布林 | J9: 118
C10: 5 | D10: 中浅焙 | E10: 200克 | F10: 花韵 果香 | G10: ♤♤♤♤ | H10: 花魁XS | I10: 埃塞俄比亚谷吉汉贝拉正宗2025花魁XS限量版 #紫葡萄 #蓝莓 #草莓水果糖 #香水月季 #高甜丰厚的果汁感 | J10: 118
C11: 6 | D11: 中浅焙 | E11: 200克 | F11: 优雅 果香 | G11: ♤♤♤♤ | H11: 赤拉客厌氧 | I11: 埃塞俄比亚班莎ALO赤拉客厌G1厌氧日晒（高甜度厚口感非常好喝） #蓝莓 #树莓 #柑橘 #花香 #黄桃般丰厚略有粘度的好口感 | J11: 118
C12: 7 | D12: 中焙 | E12: 200克 | F12: 巧克力调性 | G12: ♤♤ | H12: 谷吉低因 | I12: 埃塞俄比亚谷吉日晒山水处理法真·低因咖啡 （无负担喝咖啡者的必备品） #焦糖巧克力 #橘皮 #红糖 #甜香温和，质地甘醇无负担 | J12: 66
C13: 8 | D13: 中浅焙 | E13: 200克 | F13: 莓果花香 | G13: ♤♤♤♤ | H13: 莓宴 | I13: 肯尼亚奇安布奥克兰庄园-莓宴（AA TOP规格） #黑莓 #蓝莓 #覆盆子 #苹果花 #血橙 #果汁感强，酸甜愉悦又饱满 | J13: 110
C14: 9 | D14: 中浅焙 | E14: 200克 | F14: 莓果花香 | G14: ♤♤♤♤ | H14: 瓦姆古玛AA | I14: 肯尼亚尼耶利瓦姆古玛AA（AA TOP规格） #乌莓 #柑橘 #蔓越莓 #酸甜感较柔和 | J14: 110
C15: 10 | D15: 中深焙 | E15: 200克 | F15: 醇甜厚实 巧克力浓香 | G15: ♤ | H15: 蜜可可 | I15: 肯尼亚尼耶利蜜可可Mielcoco（饱饱的厚甜感又顺滑哦） #巧克力 #锡兰红茶 #小白杏 #柴烧黑糖 顺滑厚实甜美 | J15: 75
B16: 中南美洲 | C16: 11 | D16: 中浅焙 | E16: 200克 | F16: 果香与香料 | G16: ♤♤♤♤ | H16: 愉悦蜜处理 | I16: 哥伦比亚金迪奥愉悦庄园蜜处理粉波旁 #轻发酵柑橘 #柠檬马鞭草 #蜜李 #清爽温和又顺口的高级特色咖啡 | J16: 168
C17: 12 | D17: 中浅焙 | E17: 200克 | F17: 特色香草植物 发酵果香 | G17: ♤♤♤♤ | H17: 愉悦Wush Wush | I17: 哥伦比亚金迪奥愉悦庄园黑蜜条纹橙Wush Wush #烤红椒 #柠檬草 #花香 #风味独特强劲，特色鲜明 | J17: 168
C18: 13 | D18: 中浅焙 | E18: 200克 | F18: 特色清酒香 | G18: ♤♤♤♤ | H18: 天堂92条纹波旁 | I18: 哥伦比亚考卡天堂92日本清酒曲厌氧水洗条纹波旁 #清酒 #粉色花香 #荔枝 #口感活泼余韵悠长 | J18: 368
C19: 14 | D19: 中浅焙 | E19: 200克 | F19: 高浓度多层次 莓果水果浓香 | G19: ♤♤♤♤ | H19: 分界线庄园希爪 | I19: ★★★★哥伦比亚分界线庄园双重发酵日晒希爪Sidra（好喝到炸裂！浓郁复合果汁） #复合莓果汁 #杏桃 #紫色水果 #紫色花香 #口感质地细腻饱满甜美 | J19: 358
C20: 15 | D20: 中焙 | E20: 200克 | F20: 蜜糖甜李花香 | G20: ♤♤ | H20: 分界线瑰夏 | I20: ★★★★哥伦比亚分界线庄园水洗瑰夏（名庄瑰夏，性价比高！） #蜂糖李 #槐花蜜 #鲜炒绿茶尾韵 #口感甜厚圆润愉悦 | J20: 240
C21: 16 | D21: 中浅焙 | E21: 200克 | F21: 浓郁 果干爆香 | G21: ♤♤♤♤ | H21: 90+埃莱塔瑰夏 | I21: 巴拿马沃肯90+ Eleta埃莱塔瑰夏特殊处理法（高端品牌风味强度就是高） #蜜渍凤梨 #佛手柑 #柚子 #口感丰富酸甜活泼 | J21: 380
C22: 17 | D22: 中焙 | E22: 200克 | F22: 圆润 果香 | G22: ♤♤♤ | H22: 小甜心瑰夏 | I22: 秘鲁小甜心瑰夏 #红李 #红杏 #柑橘 #淡花香 #口感温和，温润平衡顺口 | J22: 128
C23: 18 | D23: 中焙 | E23: 200克 | F23: 圆润 果香 | G23: ♤♤ | H23: 蓝山 | I23: 牙买加斯东尼庄园蓝山一号铁比卡（正宗蓝山中的优质货，送礼好选） #蜜糖杏李 #高质感巧克力 #甜榛子 #丝滑平衡无敌的口感 | J23: 430
B24: 亚洲 | C24: 19 | D24: 中焙 | E24: 200克 | F24: 高浓度多层次 莓果水果浓香 | G24: ♤♤ | H24: DR132 | I24: 西双版纳孟宋高海拔新品种DR132厌氧日晒(稀有!黄果皮变种卡蒂姆） #青芒 #生姜花 #肉豆蔻 #糖蜜与热带水果甜 | J24: 98
C25: 20 | D25: 中焙 | E25: 200克 | F25: 坚果糖蜜 | G25: ♤♤♤ | H25: 云佳蜜 | I25: 云南临沧云佳庄园日晒云佳蜜（临沧精品咖啡协会会长稳定生产口粮级别好豆！） #巴旦木 #糖蜜 #轻发酵果干 | J25: 66
C26: 21 | D26: 中焙 | E26: 200克 | F26: 高雅 蜜甜核果香 | G26: ♤♤♤ | H26: 太阳鸟 | I26: 西双版纳西定云乐庄园高海拔水洗巴蒂安Batian巴天太阳鸟（稀有品种，高质感） #蔓越莓 #柑橘 #玫瑰李 #高活泼酸甜醇厚咖啡 | J26: 168
C27: 22 | D27: 中深焙 | E27: 200克 | F27: 浓香 | G27: ♤♤ | H27: 日光曼特宁 | I27: ☆苏门答腊日光曼特宁(经典曼特宁的甜香风格) #森林气息 #焦糖 #坚果黑可可 | J27: 78
C28: 23 | D28: 中深焙 | E28: 200克 | F28: 浓香 | G28: ♤♤ | H28: 白金曼特宁 | I28: ★★苏门答腊迦幼山白金曼特宁水洗处理法（颗粒又大又长，十分漂亮） #仙草 #糖蜜 #黑巧克力 #黑李甜酸 #质感厚重却十足干净 | J28: 98
C29: 24 | D29: 中焙 | E29: 200克 | F29: 圆润 果香 | G29: ♤♤ | H29: 兰特卡鲁瓦 | I29: 苏拉威西托拉贾兰特卡鲁瓦日晒 #苹果 #樱桃 #核果 #柠檬草 #温润口感顺滑浑厚 | J29: 118
B30: 大洋洲 | C30: 25 | D30: 中浅焙 | E30: 200克 | F30: 高雅 花果香 | G30: ♤♤♤ | H30: 科布兰瑰夏 | I30: 巴布亚新几内亚巴罗伊达庄园科布兰水洗瑰夏 #玫瑰果 #红心猕猴桃 #树莓 #奶油草莓 #甜酸美味，果汁感十足 | J30: 228
B31: 折石 配方 咖啡 （意式） | C31: 26 | D31: 深焙 | E31: 500克 | F31: 威力 浓香 | G31: ♤ | H31: 黑洞 | I31: ☆★无负担配方设计 黑洞/500克装（经典产品，推荐咖啡店意式市使用首选） （孟连+普洱+哥伦比亚+西达摩） #厚重苦甜巧克力 #核果甜香 #重焦糖 #饱满却不苦涩，奶咖的绝配 | J31: 110
C32: 27 | D32: 中深焙 | E32: 500克 | F32: 圆润 坚果与果香 | G32: ♤♤ | H32: 流星 | I32: ☆★无负担配方设计 流星/500克装（经典产品，咖啡店首选）（孟连+普洱+西达摩） #锡兰红茶 #甜杏李 #坚果 #口感温润，轻盈柔顺不迟腻 | J32: 110
C33: 28 | D33: 中焙 | E33: 500克 | F33: 圆润 果香与甜香 | G33: ♤♤ | H33: 天之语 | I33: 细腻感配方设计 天之语 500克装（埃塞水洗&日晒+巴西+哥伦比亚） #红糖蜜 #烤橘香 #奶油巧克力 #柔顺干净追求平衡的典范口感 | J33: 120
C34: 29 | D34: 中浅焙 | E34: 500克 | F34: 多层次 花果香 | G34: ♤♤♤ | H34: 花宙2.0 | I34: ★★细腻感配方设计 花宙2.0甜美式配方（埃塞日晒+肯尼亚+哥伦比亚+耶加） #甜柑橘 #鲜红莓 #核果蜜香 #清爽上扬果汁感甜酸质地 | J34: 125
C35: 30 | D35: 深焙 | E35: 500克 | F35: 厚重 多层次浓香 | G35: ♤ | H35: 充电桩 | I35: ★★★★盲盒配方 充电桩/500克装（主基调一致 每批次细节不同，重口味者的心头好） #巧克力 #重焦糖 #朗姆威士忌 #入口丰富 #口感饱满尾韵层次 | J35: 110
B36: 折石定制 浓缩液 | C36: 31 | D36: 深焙 | E36: 30ml | F36: 威力 浓香 | G36: ♤ | H36: 黑洞浓缩液 散装 | I36: 黑洞浓缩液咖啡散装（单条30ml装，无外盒，每条可冲得180~240ml咖啡） #苦甜巧克力 #核果甜香 #黑糖 #饱满不苦涩，奶咖绝配 | J36: 5.5
C37: 32 | D37: 深焙 | E37: 20条 | F37: 威力 浓香 | G37: ♤ | H37: 黑洞浓缩液 20入盒装 | I37: 黑洞浓缩液咖啡20入盒装（透明盒装20条，每条可冲得180~240ml咖啡） #苦甜巧克力 #核果甜香 #黑糖 #饱满不苦涩，奶咖绝配 | J37: 98
B38: 以上商户合作优惠价与大量订购批发价含税不含运
H39: 扫描付款方式
B41: ★热门推荐
B42: ★★ 强力推荐
...

Sheet 豆单_批发（2602)
B2: 订购前请先看以下说明 单品豆规格皆为200克装，大量订购优惠的[200克]24包是针对单品豆的批发条件 意式豆皆为500克装，大量订购优惠的[500克]32包是针对意式豆的批发条件 咖啡豆需要满足单一品项的数量才能获得该品项的优惠价 ＊咖啡通常会有常备库存，7天内烘焙的库存会直接出货 ＊下单后三工作日内烘焙发货（周末休息） ＊ 商户合作优惠优惠无最低起订量，但您若能尽量单品豆以4包倍数订购，意式豆以2包500克为单位订购，我们将无比感谢您 ＊ 合作商户享大量订购优惠价，意式豆请按32包倍数订购，单品豆按24包倍数订购 ＊ 大量订购我们能够用上大机器烘焙，将省下来的时间回馈给您，有能力可以多订一些，更加优惠哦
B3: ＊付款请支付下方三个公司户收款方式，不用个人微信收款~敬请见谅＊
B4: 折石咖啡 江承哲严选咖啡豆单
B5: 产区 | C5: 序号 | D5: 烘焙度 | E5: 规格 | F5: 香型 | G5: 果酸感 | H5: 简称 | I5: 咖啡/商品名称 | J5: 享味价 | K5: 商户合作优惠 [200克]4包/件 [500克]2包/件 | L5: 大量订购优惠 [200克]24包 [500克]32包 | M5: 超大量优惠 [200克]60包 [500克]96包
B6: 非洲 | C6: 1 | D6: 中浅焙 | E6: 200克 | F6: 清新 果香 | G6: ♤♤♤♤ | H6: 柠檬花 | I6: ★★★（经典畅销）埃塞俄比亚耶加雪菲柠檬花 #清香柠檬花 #蜂蜜红茶 #轻焦糖 #甜酸明亮愉悦 | J6: 66 | K6: 50 | L6: 46 | M6: 40
C7: 2 | D7: 中焙 | E7: 200克 | F7: 蜜香红茶 柑橘甜 | G7: ♤♤ | H7: 蜜香摩卡 | I7: 埃塞俄比亚耶加雪菲蜜香摩卡 #蜂蜜 #柑橘 #锡兰红茶 #淡花香 #甜美温和口感舒爽有厚度 | J7: 66 | K7: 50 | L7: 46 | M7: 40
C8: 3 | D8: 深焙 | E8: 200克 | F8: 厚重 浓香 | G8: ♤ | H8: 黑美人 | I8: 埃塞俄比亚耶加雪菲摩卡黑美人（深烘焙精品咖啡的典范） #焦糖烤橘子 #可可 #豆蔻 #甘甜醇香 | J8: 66 | K8: 50 | L8: 46 | M8: 40
C9: 4 | D9: 中浅焙 | E9: 200克 | F9: 花韵 果香 | G9: ♤♤♤♤ | H9: 塔拉图 | I9: 埃塞俄比亚耶加雪菲班科塔拉图G1双重厌氧水洗 （中国之选铂金奖，相当好喝） #高级橙花 #柠檬 #棉花糖 #红布林 | J9: 118 | K9: 88 | L9: 82 | M9: 72
C10: 5 | D10: 中浅焙 | E10: 200克 | F10: 花韵 果香 | G10: ♤♤♤♤ | H10: 花魁XS | I10: 埃塞俄比亚谷吉汉贝拉正宗2025花魁XS限量版 #紫葡萄 #蓝莓 #草莓水果糖 #香水月季 #高甜丰厚的果汁感 | J10: 118 | K10: 88 | L10: 82 | M10: 72
C11: 6 | D11: 中浅焙 | E11: 200克 | F11: 优雅 果香 | G11: ♤♤♤♤ | H11: 赤拉客厌氧 | I11: 埃塞俄比亚班莎ALO赤拉客厌G1厌氧日晒 #蓝莓 #树莓 #柑橘 #花香 #黄桃般丰厚略有粘度的好口感 | J11: 118 | K11: 88 | L11: 82 | M11: 72
C12: 7 | D12: 中浅焙 | E12: 200克 | F12: 莓果花香 | G12: ♤♤♤♤ | H12: 肯尼亚紫花 | I12: 肯尼亚基隆贝SL28 SL34（AA TOP规格） #紫色花香#鲜蓝莓#西梅#柑橘,丰富甜美独到浓香 | J12: 168 | K12: =J12*0.7 -> 117.6 | L12: 100 | M12: =J12*0.5 -> 84
C13: 8 | D13: 中浅焙 | E13: 200克 | F13: 莓果花香 | G13: ♤♤♤♤ | H13: 莓宴 | I13: 肯尼亚奇安布奥克兰庄园-莓宴（AA TOP规格） #黑莓 #蓝莓 #覆盆子 #苹果花 #血橙 #果汁感强，酸甜愉悦又饱满 | J13: 110 | K13: =J13*0.7 -> 77 | L13: 72 | M13: 66
C14: 9 | D14: 中浅焙 | E14: 200克 | F14: 莓果花香 | G14: ♤♤♤♤ | H14: 瓦姆古玛AA | I14: 肯尼亚尼耶利瓦姆古玛AA（AA TOP规格） #乌莓 #柑橘 #蔓越莓 #酸甜感较柔和 | J14: 110 | K14: =J14*0.7 -> 77 | L14: 72 | M14: 66
C15: 10 | D15: 中深焙 | E15: 200克 | F15: 醇甜厚实 巧克力浓香 | G15: ♤ | H15: 蜜可可 | I15: 肯尼亚尼耶利蜜可可Mielcoco（饱饱的厚甜感又顺滑哦） #巧克力 #锡兰红茶 #小白杏 #柴烧黑糖 顺滑厚实甜美 | J15: 75 | K15: 55 | L15: 49 | M15: 45
B16: 中南美洲 | C16: 11 | D16: 中浅焙 | E16: 200克 | F16: 果香与香料 | G16: ♤♤♤♤ | H16: 愉悦蜜处理 | I16: 哥伦比亚金迪奥愉悦庄园蜜处理粉波旁 #轻发酵柑橘 #柠檬马鞭草 #蜜李 #清爽温和又顺口的高级特色咖啡 | J16: 168 | K16: =J16*0.7 -> 117.6 | L16: 100 | M16: =J16*0.5 -> 84
C17: 12 | D17: 中浅焙 | E17: 200克 | F17: 特色香草植物 发酵果香 | G17: ♤♤♤♤ | H17: 愉悦Wush Wush | I17: 哥伦比亚金迪奥愉悦庄园黑蜜条纹橙Wush Wush #烤红椒 #柠檬草 #花香 #风味独特强劲，特色鲜明 | J17: 168 | K17: 118 | L17: 100 | M17: 84
C18: 13 | D18: 中浅焙 | E18: 200克 | F18: 特色清酒香 | G18: ♤♤♤♤ | H18: 天堂92条纹波旁 | I18: ★★★★★哥伦比亚考卡天堂92日本清酒曲厌氧水洗条纹波旁 #清酒 #粉色花香 #荔枝 #口感活泼余韵悠长 | J18: ¥368 ¥295 | K18: 221 | L18: 177 | M18: 148
C19: 14 | D19: 中浅焙 | E19: 200克 | F19: 多层次 果香酒韵 | G19: ♤♤ | H19: 天堂92朗姆酒 | I19: ★★★★★哥伦比亚考卡天堂92啤酒酵母+朗姆酒桶静置（焙度加深！更加厚重好喝） #黑朗姆酒 #焦糖巧克力 #啤酒花 #层次多元口感爽口厚重 | J19: ¥208 ¥168 | K19: 126 | L19: 118 | M19: 109
C20: 15 | D20: 中浅焙 | E20: 200克 | F20: 高浓度多层次 莓果水果浓香 | G20: ♤♤♤♤ | H20: 分界线庄园希爪 | I20: ★★★★哥伦比亚分界线庄园双重发酵日晒希爪Sidra（好喝到炸裂！浓郁复合果汁） #复合莓果汁 #杏桃 #紫色水果 #紫色花香 #口感质地细腻饱满甜美 | J20: 358 | K20: =J20*0.75 -> 268.5 | L20: 215 | M20: 179
C21: 16 | D21: 中焙 | E21: 200克 | F21: 蜜糖甜李花香 | G21: ♤♤ | H21: 分界线瑰夏 | I21: ★★★★哥伦比亚分界线庄园水洗瑰夏（名庄瑰夏，性价比高！） #蜂糖李 #槐花蜜 #鲜炒绿茶尾韵 #口感甜厚圆润愉悦 | J21: 240 | K21: 180 | L21: 170 | M21: 160
C22: 17 | D22: 中浅焙 | E22: 200克 | F22: 浓郁 果干爆香 | G22: ♤♤♤♤ | H22: 90+埃莱塔瑰夏 | I22: ★★★★★巴拿马沃肯90+ Eleta埃莱塔瑰夏特殊处理法（高端品牌风味强度就是高） #蜜渍凤梨 #佛手柑 #柚子 #口感丰富酸甜活泼 | J22: ¥380 ¥300 | K22: 225 | L22: 212 | M22: 200
C23: 18 | D23: 中焙 | E23: 200克 | F23: 圆润 果香 | G23: ♤♤♤ | H23: 黛博拉瑰夏 | I23: ★★★★巴拿马沃坎 Savage萨维奇·黛博拉庄园“星空”瑰夏 酵母发酵日晒（世界冠军级庄园，层次繁复且极具张力） #奶油草莓 #桑葚 #山楂葡萄干 #口感丝滑甜感炸裂 | J23: 920 | K23: 690 | L23: 550 | M23: 460
C24: 19 | D24: 中焙 | E24: 200克 | F24: 圆润 果香 | G24: ♤♤ | H24: 蓝山 | I24: 牙买加斯东尼庄园蓝山一号铁比卡（正宗蓝山中的优质货，送礼好选） #蜜糖杏李 #高质感巧克力 #甜榛子 #丝滑平衡无敌的口感 | J24: 430 | K24: 300 | L24: 258 | M24: 215
B25: 亚洲 | C25: 20 | D25: 中焙 | E25: 200克 | F25: 高浓度多层次 莓果水果浓香 | G25: ♤♤ | H25: DR132 | I25: 西双版纳孟宋高海拔新品种DR132厌氧日晒(稀有!黄果皮变种卡蒂姆） #青芒 #生姜花 #肉豆蔻 #糖蜜与热带水果甜 | J25: 98 | K25: 75 | L25: 70 | M25: 65
C26: 21 | D26: 中焙 | E26: 200克 | F26: 坚果糖蜜 | G26: ♤♤♤ | H26: 云佳蜜 | I26: 云南临沧云佳庄园日晒云佳蜜（临沧精品咖啡协会会长稳定生产口粮级别好豆！） #巴旦木 #糖蜜 #轻发酵果干 | J26: 66 | K26: 50 | L26: 46 | M26: 50
C27: 22 | D27: 中焙 | E27: 200克 | F27: 高雅 蜜甜核果香 | G27: ♤♤♤ | H27: 太阳鸟 | I27: 西双版纳西定云乐庄园高海拔水洗巴蒂安Batian巴天太阳鸟（稀有品种，高质感） #蔓越莓 #柑橘 #玫瑰李 #高活泼酸甜醇厚咖啡 | J27: 168 | K27: 126 | L27: 118 | M27: 109
C28: 23 | D28: 中深焙 | E28: 200克 | F28: 浓香 | G28: ♤♤ | H28: 日光曼特宁 | I28: ★苏门答腊日光曼特宁(经典曼特宁的甜香风格) #森林气息 #焦糖 #坚果黑可可 | J28: 78 | K28: 60 | L28: 55 | M28: 50
C29: 24 | D29: 中深焙 | E29: 200克 | F29: 浓香 | G29: ♤♤ | H29: 白金曼特宁 | I29: ★★苏门答腊迦幼山白金曼特宁水洗处理法（颗粒又大又长，十分漂亮） #仙草 #糖蜜 #黑巧克力 #黑李甜酸 #质感厚重却十足干净 | J29: 98 | K29: 75 | L29: 70 | M29: 65
C30: 25 | D30: 中深焙 | E30: 200克 | F30: 浓香 | G30: ♤♤ | H30: 林东之星 | I30: ★★★★苏门答腊多巴湖林东之星（风味深沉内敛，拥有曼特宁中少见的极高净度） #雪松木 #回甘草本 #黑巧克力 #西柚微酸 #口感如糖浆般粘稠 | J30: 118 | K30: 88 | L30: 82 | M30: 72
C31: 26 | D31: 中焙 | E31: 200克 | F31: 圆润 果香 | G31: ♤♤ | H31: 兰特卡鲁瓦 | I31: 苏拉威西托拉贾兰特卡鲁瓦日晒 #苹果 #樱桃 #核果 #柠檬草 #温润口感顺滑浑厚 | J31: 118 | K31: 88 | L31: 82 | M31: 72
B32: 折石 配方 咖啡 （意式） | C32: 27 | D32: 深焙 | E32: 500克 | F32: 威力 浓香 | G32: ♤ | H32: 黑洞 | I32: ★★无负担配方设计 黑洞/500克装（经典产品，推荐咖啡店意式市使用首选） （孟连+普洱+哥伦比亚+西达摩） #厚重苦甜巧克力 #核果甜香 #重焦糖 #饱满却不苦涩，奶咖的绝配 | J32: 110 | K32: 80 | L32: 70 | M32: 65
C33: 28 | D33: 中深焙 | E33: 500克 | F33: 圆润 坚果与果香 | G33: ♤♤ | H33: 流星 | I33: ★★无负担配方设计 流星/500克装（经典产品，咖啡店首选）（孟连+普洱+西达摩） #锡兰红茶 #甜杏李 #坚果 #口感温润，轻盈柔顺不迟腻 | J33: 110 | K33: 80 | L33: 70 | M33: 65
C34: 29 | D34: 中焙 | E34: 500克 | F34: 圆润 果香与甜香 | G34: ♤♤ | H34: 天之语 | I34: 细腻感配方设计 天之语 500克装（埃塞水洗&日晒+巴西+哥伦比亚） #红糖蜜 #烤橘香 #奶油巧克力 #柔顺干净追求平衡的典范口感 | J34: 120 | K34: 90 | L34: 80 | M34: 75
C35: 30 | D35: 中浅焙 | E35: 500克 | F35: 多层次 花果香 | G35: ♤♤♤ | H35: 花宙2.0 | I35: ★★细腻感配方设计 花宙2.0甜美式配方（埃塞日晒+肯尼亚+哥伦比亚+耶加） #甜柑橘 #鲜红莓 #核果蜜香 #清爽上扬果汁感甜酸质地 | J35: 125 | K35: 95 | L35: 85 | M35: 80
C36: 31 | D36: 深焙 | E36: 500克 | F36: 厚重 多层次浓香 | G36: ♤ | H36: 充电桩 | I36: ★★★★盲盒配方 充电桩/500克装（主基调一致 每批次细节不同，重口味者的心头好） #巧克力 #重焦糖 #朗姆威士忌 #入口丰富 #口感饱满尾韵层次 | J36: 110 | K36: 80 | L36: 70 | M36: 65
B37: 折石定制 浓缩液 | C37: 32 | D37: 深焙 | E37: 30ml | F37: 威力 浓香 | G37: ♤ | H37: 黑洞浓缩液 散装 | I37: 黑洞浓缩液咖啡散装（单条30ml装，无外盒，每条可冲得180~240ml咖啡） #苦甜巧克力 #核果甜香 #黑糖 #饱满不苦涩，奶咖绝配 | J37: 5.5 | K37: ￥3.5 任意数量 | L37: ￥3 100条起 | M37: ￥2.5 1000条起
C38: 33 | D38: 深焙 | E38: 20条 | F38: 威力 浓香 | G38: ♤ | H38: 黑洞浓缩液 20入盒装 | I38: 黑洞浓缩液咖啡20入盒装（透明盒装20条，每条可冲得180~240ml咖啡） #苦甜巧克力 #核果甜香 #黑糖 #饱满不苦涩，奶咖绝配 | J38: 98 | K38: ￥72 任意数量 | L38: ￥62 5盒起 | M38: ￥52 50盒起
B39: 以上商户合作优惠价与大量订购批发价含税不含运
H40: 扫描付款方式
B42: ★热门推荐 | D42: ★★★经典畅销
...

Sheet 定价表
A1: 商品编号 | B1: 焙度 | C1: 香型 | D1: 果酸感 | E1: 产品内部名称 | F1: 规格 | G1: 生豆成本 kg | H1: 成本 | I1: 淘宝 一口价 | J1: 享味价 | K1: 享味价 毛利率 | L1: 淘宝 普通会员 9.5折 | M1: 淘宝 高级会员 7.2折 | N1: 淘宝 VIP会员 6.8折 | O1: 淘宝 至尊VIP 6.4折 | P1: 商户合作优惠 [200克]4包/件 [500克]2包/件 | Q1: 商户合作优惠 毛利率 | R1: 大量订购优惠 [200克]24包 [500克]32包 | S1: 大量订购优惠 毛利率 | T1: 超大量优惠 [200克]60包 [500克]96包 | U1: 超大量优惠 毛利率
P2: =P3/J3 -> 0.75757576 | R2: =R3/J3 -> 0.6969697 | T2: =T3/J3 -> 0.60606061
E3: 柠檬花 | F3: 200克 | G3: 70 | H3: =G3*0.25+2 -> 19.5 | I3: =ROUNDDOWN(J3*1.3,0) -> 85 | J3: 66 | K3: =(J3-H3)/J3 -> 0.70454545 | L3: =I3*0.95 -> 80.75 | M3: =I3*0.72 -> 61.2 | N3: =I3*0.68 -> 57.8 | O3: =I3*0.64 -> 54.4 | P3: 50 | Q3: =(P3-H3)/P3 -> 0.61 | R3: 46 | S3: =(R3-H3)/R3 -> 0.57608696 | T3: 40 | U3: =(T3-H3)/T3 -> 0.5125
E4: 蜜香摩卡 | F4: 200克 | H4: =65*0.25+2 -> 18.25 | I4: =ROUNDDOWN(J4*1.3,0) -> 85 | J4: 66 | K4: =(J4-H4)/J4 -> 0.72348485 | L4: =I4*0.95 -> 80.75 | M4: =I4*0.72 -> 61.2 | N4: =I4*0.68 -> 57.8 | O4: =I4*0.64 -> 54.4 | P4: 48 | Q4: =(P4-H4)/P4 -> 0.61979167 | R4: 42 | S4: =(R4-H4)/R4 -> 0.56547619 | T4: 38 | U4: =(T4-H4)/T4 -> 0.51973684
E5: 黑美人 | F5: 200克 | H5: =65*0.25+2 -> 18.25 | I5: =ROUNDDOWN(J5*1.3,0) -> 85 | J5: 66 | K5: =(J5-H5)/J5 -> 0.72348485 | L5: =I5*0.95 -> 80.75 | M5: =I5*0.72 -> 61.2 | N5: =I5*0.68 -> 57.8 | O5: =I5*0.64 -> 54.4 | P5: 165 | Q5: =(P5-H5)/P5 -> 0.88939394 | R5: 154 | S5: =(R5-H5)/R5 -> 0.88149351 | T5: 142 | U5: =(T5-H5)/T5 -> 0.87147887
E6: 蝴洛儿 | F6: 200克 | H6: =75.1/800*200+2 -> 20.775 | I6: =ROUNDDOWN(J6*1.3,0) -> 127 | J6: 98 | K6: =(J6-H6)/J6 -> 0.7880102 | L6: =I6*0.95 -> 120.65 | M6: =I6*0.72 -> 91.44 | N6: =I6*0.68 -> 86.36 | O6: =I6*0.64 -> 81.28 | P6: 75 | Q6: =(P6-H6)/P6 -> 0.723 | R6: 70 | S6: =(R6-H6)/R6 -> 0.70321429 | T6: 65 | U6: =(T6-H6)/T6 -> 0.68038462
E7: 花魁XS | F7: 200克 | H7: =_xlfn.XLOOKUP(E7,生豆成本表!$B$2:$B$35,生豆成本表!$C$2:$C$35)/800*200+2 -> 38.5 | I7: =ROUNDDOWN(J7*1.3,0) -> 153 | J7: 118 | K7: =(J7-H7)/J7 -> 0.67372881 | L7: =I7*0.95 -> 145.35 | M7: =I7*0.72 -> 110.16 | N7: =I7*0.68 -> 104.04 | O7: =I7*0.64 -> 97.92 | P7: 75 | Q7: =(P7-H7)/P7 -> 0.48666667 | R7: 70 | S7: =(R7-H7)/R7 -> 0.45 | T7: 65 | U7: =(T7-H7)/T7 -> 0.40769231
E8: 乌拉嘎提波哈洛 | F8: 200克 | H8: =_xlfn.XLOOKUP(E8,生豆成本表!$B$2:$B$35,生豆成本表!$C$2:$C$35)/800*200+2 -> 46.5 | I8: =ROUNDDOWN(J8*1.3,0) -> 231 | J8: 178 | K8: =(J8-H8)/J8 -> 0.73876404 | L8: =I8*0.95 -> 219.45 | M8: =I8*0.72 -> 166.32 | N8: =I8*0.68 -> 157.08 | O8: =I8*0.64 -> 147.84 | P8: 96 | Q8: =(P8-H8)/P8 -> 0.515625 | R8: =J8*0.7 -> 124.6 | S8: =(R8-H8)/R8 -> 0.62680578 | T8: 85 | U8: =(T8-H8)/T8 -> 0.45294118
E9: 谷吉低因 | F9: 200克 | H9: =_xlfn.XLOOKUP(E9,生豆成本表!$B$2:$B$35,生豆成本表!$C$2:$C$35)/800*200+2 -> 19 | I9: =ROUNDDOWN(J9*1.3,0) -> 85 | J9: 66 | K9: =(J9-H9)/J9 -> 0.71212121 | L9: =I9*0.95 -> 80.75 | M9: =I9*0.72 -> 61.2 | N9: =I9*0.68 -> 57.8 | O9: =I9*0.64 -> 54.4 | P9: 75 | Q9: =(P9-H9)/P9 -> 0.74666667 | R9: 70 | S9: =(R9-H9)/R9 -> 0.72857143 | T9: 65 | U9: =(T9-H9)/T9 -> 0.70769231
E10: 五号花园 | F10: 200克 | H10: =_xlfn.XLOOKUP(E10,生豆成本表!$B$2:$B$35,生豆成本表!$C$2:$C$35)/800*200+2 -> 51.5 | I10: =ROUNDDOWN(J10*1.3,0) -> 284 | J10: 219 | K10: =(J10-H10)/J10 -> 0.76484018 | L10: =I10*0.95 -> 269.8 | M10: =I10*0.72 -> 204.48 | N10: =I10*0.68 -> 193.12 | O10: =I10*0.64 -> 181.76 | P10: 85 | Q10: =(P10-H10)/P10 -> 0.39411765 | R10: 78 | S10: =(R10-H10)/R10 -> 0.33974359 | T10: 72 | U10: =(T10-H10)/T10 -> 0.28472222
E11: 肯尼亚莓宴 | F11: 200克 | H11: =_xlfn.XLOOKUP(E11,生豆成本表!$B$2:$B$36,生豆成本表!$C$2:$C$36)/800*200+2 -> 34 | I11: =ROUNDDOWN(J11*1.3,0) -> 143 | J11: 110 | K11: =(J11-H11)/J11 -> 0.69090909 | L11: =I11*0.95 -> 135.85 | M11: =I11*0.72 -> 102.96 | N11: =I11*0.68 -> 97.24 | O11: =I11*0.64 -> 91.52 | P11: 118 | Q11: =(P11-H11)/P11 -> 0.71186441 | R11: 108 | S11: =(R11-H11)/R11 -> 0.68518519 | T11: 98 | U11: =(T11-H11)/T11 -> 0.65306122
E12: 蜜可可 | F12: 200克 | H12: =69/800*200+2 -> 19.25 | I12: =ROUNDDOWN(J12*1.3,0) -> 85 | J12: 66 | K12: =(J12-H12)/J12 -> 0.70833333 | L12: =I12*0.95 -> 80.75 | M12: =I12*0.72 -> 61.2 | N12: =I12*0.68 -> 57.8 | O12: =I12*0.64 -> 54.4 | P12: 125 | Q12: =(P12-H12)/P12 -> 0.846 | R12: 115 | S12: =(R12-H12)/R12 -> 0.8326087 | T12: 105 | U12: =(T12-H12)/T12 -> 0.81666667
E13: 天堂92朗姆酒 | F13: 200克 | H13: =_xlfn.XLOOKUP(E13,生豆成本表!$B$2:$B$35,生豆成本表!$C$2:$C$35)/800*200+2 -> 51.5 | I13: =ROUNDDOWN(J13*1.3,0) -> 270 | J13: 208 | K13: =(J13-H13)/J13 -> 0.75240385 | L13: =I13*0.95 -> 256.5 | M13: =I13*0.72 -> 194.4 | N13: =I13*0.68 -> 183.6 | O13: =I13*0.64 -> 172.8 | P13: 60 | Q13: =(P13-H13)/P13 -> 0.14166667 | R13: 55 | S13: =(R13-H13)/R13 -> 0.063636364 | T13: 50 | U13: =(T13-H13)/T13 -> -0.03
E14: 拉斯拉哈斯H1 | F14: 200克 | H14: =_xlfn.XLOOKUP(E14,生豆成本表!$B$2:$B$35,生豆成本表!$C$2:$C$35)/800*200+2 -> 44 | I14: =ROUNDDOWN(J14*1.3,0) -> 188 | J14: 145 | K14: =(J14-H14)/J14 -> 0.69655172 | L14: =I14*0.95 -> 178.6 | M14: =I14*0.72 -> 135.36 | N14: =I14*0.68 -> 127.84 | O14: =I14*0.64 -> 120.32 | P14: 168 | Q14: =(P14-H14)/P14 -> 0.73809524 | R14: 153 | S14: =(R14-H14)/R14 -> 0.7124183 | T14: 142 | U14: =(T14-H14)/T14 -> 0.69014085
E15: 黄蜜薇拉萨奇 | F15: 200克 | H15: =_xlfn.XLOOKUP(E15,生豆成本表!$B$2:$B$35,生豆成本表!$C$2:$C$35)/800*200+2 -> 21.75 | I15: =ROUNDDOWN(J15*1.3,0) -> 93 | J15: 72 | K15: =(J15-H15)/J15 -> 0.69791667 | L15: =I15*0.95 -> 88.35 | M15: =I15*0.72 -> 66.96 | N15: =I15*0.68 -> 63.24 | O15: =I15*0.64 -> 59.52 | P15: 85 | Q15: =(P15-H15)/P15 -> 0.74411765 | R15: 78 | S15: =(R15-H15)/R15 -> 0.72115385 | T15: 72 | U15: =(T15-H15)/T15 -> 0.69791667
E16: 哥斯达黎加贝多芬 | F16: 200克 | H16: =_xlfn.XLOOKUP(E16,生豆成本表!$B$2:$B$35,生豆成本表!$C$2:$C$35)/800*200+2 -> 44.5 | I16: =ROUNDDOWN(J16*1.3,0) -> 218 | J16: 168 | K16: =(J16-H16)/J16 -> 0.73511905 | L16: =I16*0.95 -> 207.1 | M16: =I16*0.72 -> 156.96 | N16: =I16*0.68 -> 148.24 | O16: =I16*0.64 -> 139.52 | P16: 46 | Q16: =(P16-H16)/P16 -> 0.032608696 | R16: 40 | S16: =(R16-H16)/R16 -> -0.1125 | T16: 36 | U16: =(T16-H16)/T16 -> -0.23611111
E17: 翡翠绿标 艾薇罗 | F17: 200克 | H17: =_xlfn.XLOOKUP(E17,生豆成本表!$B$2:$B$35,生豆成本表!$C$2:$C$35)/800*200+2 -> 197 | I17: =ROUNDDOWN(J17*1.3,0) -> 975 | J17: 750 | K17: =(J17-H17)/J17 -> 0.73733333 | L17: =I17*0.95 -> 926.25 | M17: =I17*0.72 -> 702 | N17: =I17*0.68 -> 663 | O17: =I17*0.64 -> 624 | P17: 52 | Q17: =(P17-H17)/P17 -> -2.7884615 | R17: 48 | S17: =(R17-H17)/R17 -> -3.1041667 | T17: 45 | U17: =(T17-H17)/T17 -> -3.3777778
E18: 90+埃莱塔瑰夏 | F18: 200克 | H18: =_xlfn.XLOOKUP(E18,生豆成本表!$B$2:$B$35,生豆成本表!$C$2:$C$35)/800*200+2 -> 99.5 | I18: =ROUNDDOWN(J18*1.3,0) -> 637 | J18: 490 | K18: =(J18-H18)/J18 -> 0.79693878 | L18: =I18*0.95 -> 605.15 | M18: =I18*0.72 -> 458.64 | N18: =I18*0.68 -> 433.16 | O18: =I18*0.64 -> 407.68 | P18: 46 | Q18: =(P18-H18)/P18 -> -1.1630435 | R18: 40 | S18: =(R18-H18)/R18 -> -1.4875 | T18: 36 | U18: =(T18-H18)/T18 -> -1.7638889
E19: 分界线庄园希爪 | F19: 200克 | H19: =_xlfn.XLOOKUP(E19,生豆成本表!$B$2:$B$35,生豆成本表!$C$2:$C$35)/800*200+2 -> 99 | I19: =ROUNDDOWN(J19*1.3,0) -> 465 | J19: 358 | K19: =(J19-H19)/J19 -> 0.72346369 | L19: =I19*0.95 -> 441.75 | M19: =I19*0.72 -> 334.8 | N19: =I19*0.68 -> 316.2 | O19: =I19*0.64 -> 297.6 | P19: 600 | Q19: =(P19-H19)/P19 -> 0.835 | R19: x | S19: =(R19-H19)/R19 -> #VALUE! | T19: x | U19: =(T19-H19)/T19 -> #VALUE!
E20: 天堂92条纹波旁 | F20: 200克 | H20: =_xlfn.XLOOKUP(E20,生豆成本表!$B$2:$B$35,生豆成本表!$C$2:$C$35)/800*200+2 -> 70.375 | I20: =ROUNDDOWN(J20*1.3,0) -> 478 | J20: 368 | K20: =(J20-H20)/J20 -> 0.80876359 | L20: =I20*0.95 -> 454.1 | M20: =I20*0.72 -> 344.16 | N20: =I20*0.68 -> 325.04 | O20: =I20*0.64 -> 305.92 | P20: 81 | Q20: =(P20-H20)/P20 -> 0.13117284 | R20: 76 | S20: =(R20-H20)/R20 -> 0.074013158 | T20: 70 | U20: =(T20-H20)/T20 -> -0.0053571429
E21: 分界线瑰夏 | F21: 200克 | H21: =_xlfn.XLOOKUP(E21,生豆成本表!$B$2:$B$35,生豆成本表!$C$2:$C$35)/800*200+2 -> 61.5 | I21: =ROUNDDOWN(J21*1.3,0) -> 517 | J21: 398 | K21: =(J21-H21)/J21 -> 0.84547739 | L21: =I21*0.95 -> 491.15 | M21: =I21*0.72 -> 372.24 | N21: =I21*0.68 -> 351.56 | O21: =I21*0.64 -> 330.88 | P21: 89 | Q21: =(P21-H21)/P21 -> 0.30898876 | R21: 83 | S21: =(R21-H21)/R21 -> 0.25903614 | T21: 76 | U21: =(T21-H21)/T21 -> 0.19078947
E22: 蓝山康丘特 | F22: 200克 | H22: =_xlfn.XLOOKUP(E22,生豆成本表!$B$2:$B$35,生豆成本表!$C$2:$C$35)/800*200+2 -> 139.5 | I22: =ROUNDDOWN(J22*1.3,0) -> 624 | J22: 480 | K22: =(J22-H22)/J22 -> 0.709375 | L22: =I22*0.95 -> 592.8 | M22: =I22*0.72 -> 449.28 | N22: =I22*0.68 -> 424.32 | O22: =I22*0.64 -> 399.36 | P22: 156 | Q22: =(P22-H22)/P22 -> 0.10576923 | R22: 146 | S22: =(R22-H22)/R22 -> 0.044520548 | T22: 135 | U22: =(T22-H22)/T22 -> -0.033333333
E23: DR132 | F23: 200克 | H23: =_xlfn.XLOOKUP(E23,生豆成本表!$B$2:$B$35,生豆成本表!$C$2:$C$35)/800*200+2 -> 25.75 | I23: =ROUNDDOWN(J23*1.3,0) -> 127 | J23: 98 | K23: =(J23-H23)/J23 -> 0.7372449 | L23: =I23*0.95 -> 120.65 | M23: =I23*0.72 -> 91.44 | N23: =I23*0.68 -> 86.36 | O23: =I23*0.64 -> 81.28 | P23: 75 | Q23: =(P23-H23)/P23 -> 0.65666667 | R23: 70 | S23: =(R23-H23)/R23 -> 0.63214286 | T23: 65 | U23: =(T23-H23)/T23 -> 0.60384615
E24: 花恬珀 | F24: 200克 | H24: =_xlfn.XLOOKUP(E24,生豆成本表!$B$2:$B$35,生豆成本表!$C$2:$C$35)/800*200+2 -> 18 | I24: =ROUNDDOWN(J24*1.3,0) -> 101 | J24: 78 | K24: =(J24-H24)/J24 -> 0.76923077 | L24: =I24*0.95 -> 95.95 | M24: =I24*0.72 -> 72.72 | N24: =I24*0.68 -> 68.68 | O24: =I24*0.64 -> 64.64 | P24: 75 | Q24: =(P24-H24)/P24 -> 0.76 | R24: 70 | S24: =(R24-H24)/R24 -> 0.74285714 | T24: 65 | U24: =(T24-H24)/T24 -> 0.72307692
E25: 版纳紫妃 | F25: 200克 | H25: =_xlfn.XLOOKUP(E25,生豆成本表!$B$2:$B$35,生豆成本表!$C$2:$C$35)/800*200+2 -> 20 | I25: =ROUNDDOWN(J25*1.3,0) -> 97 | J25: 75 | K25: =(J25-H25)/J25 -> 0.73333333 | L25: =I25*0.95 -> 92.15 | M25: =I25*0.72 -> 69.84 | N25: =I25*0.68 -> 65.96 | O25: =I25*0.64 -> 62.08 | P25: 75 | Q25: =(P25-H25)/P25 -> 0.73333333 | R25: 70 | S25: =(R25-H25)/R25 -> 0.71428571 | T25: 65 | U25: =(T25-H25)/T25 -> 0.69230769
E26: 日光曼特宁 | F26: 200克 | H26: =71/800*200+2 -> 19.75 | I26: =ROUNDDOWN(J26*1.3,0) -> 89 | J26: 69 | K26: =(J26-H26)/J26 -> 0.71376812 | L26: =I26*0.95 -> 84.55 | M26: =I26*0.72 -> 64.08 | N26: =I26*0.68 -> 60.52 | O26: =I26*0.64 -> 56.96 | P26: 200 | Q26: =(P26-H26)/P26 -> 0.90125 | R26: x | S26: =(R26-H26)/R26 -> #VALUE! | U26: =(T26-H26)/T26 -> #DIV/0!
E27: 白金曼特宁 | F27: 200克 | H27: =78/800*200+2 -> 21.5 | I27: =ROUNDDOWN(J27*1.3,0) -> 115 | J27: 89 | K27: =(J27-H27)/J27 -> 0.75842697 | L27: =I27*0.95 -> 109.25 | M27: =I27*0.72 -> 82.8 | N27: =I27*0.68 -> 78.2 | O27: =I27*0.64 -> 73.6 | P27: 224 | Q27: =(P27-H27)/P27 -> 0.90401786 | R27: 212 | S27: =(R27-H27)/R27 -> 0.89858491 | T27: x | U27: =(T27-H27)/T27 -> #VALUE!
E28: 科布兰瑰夏 | F28: 200克 | H28: =_xlfn.XLOOKUP(E28,生豆成本表!$B$2:$B$35,生豆成本表!$C$2:$C$35)/800*200+2 -> 69 | I28: =ROUNDDOWN(J28*1.3,0) -> 296 | J28: 228 | K28: =(J28-H28)/J28 -> 0.69736842 | L28: =I28*0.95 -> 281.2 | M28: =I28*0.72 -> 213.12 | N28: =I28*0.68 -> 201.28 | O28: =I28*0.64 -> 189.44 | P28: 126 | Q28: =(P28-H28)/P28 -> 0.45238095 | R28: =118 -> 118 | S28: =(R28-H28)/R28 -> 0.41525424 | T28: =O28*0.65 -> 123.136 | U28: =(T28-H28)/T28 -> 0.43964397
E29: 黑洞 | F29: 500 | G29: =(6*65+6*68+79*4+65*4)/20+7 -> 75.7 | H29: =G29*60/96+2 -> 49.3125 | I29: =ROUNDDOWN(J29*1.3,0) -> 143 | J29: 110 | K29: =(J29-H29)/J29 -> 0.55170455 | L29: =I29*0.95 -> 135.85 | M29: =I29*0.72 -> 102.96 | N29: =I29*0.68 -> 97.24 | O29: =I29*0.64 -> 91.52 | P29: 80 | Q29: =(P29-H29)/P29 -> 0.38359375 | R29: 70 | S29: =(R29-H29)/R29 -> 0.29553571 | T29: 65 | U29: =(T29-H29)/T29 -> 0.24134615
E30: 流星 | F30: 200克 | G30: =(10*65+4*65+6*68)/20+6 -> 71.9 | H30: =G30*60/96+2 -> 46.9375 | I30: =ROUNDDOWN(J30*1.3,0) -> 143 | J30: 110 | K30: =(J30-H30)/J30 -> 0.57329545 | L30: =I30*0.95 -> 135.85 | M30: =I30*0.72 -> 102.96 | N30: =I30*0.68 -> 97.24 | O30: =I30*0.64 -> 91.52 | P30: 385 | Q30: =(P30-H30)/P30 -> 0.87808442 | R30: x | S30: =(R30-H30)/R30 -> #VALUE! | T30: x | U30: =(T30-H30)/T30 -> #VALUE!
E31: 天之语 | F31: 200克 | H31: =_xlfn.XLOOKUP(E31,生豆成本表!$B$2:$B$35,生豆成本表!$C$2:$C$35)/800*200+2 -> 19.425 | I31: =ROUNDDOWN(J31*1.3,0) -> 143 | J31: 110 | K31: =(J31-H31)/J31 -> 0.82340909 | L31: =I31*0.95 -> 135.85 | M31: =I31*0.72 -> 102.96 | N31: =I31*0.68 -> 97.24 | O31: =I31*0.64 -> 91.52 | P31: 365 | Q31: =(P31-H31)/P31 -> 0.94678082 | R31: 340 | S31: =(R31-H31)/R31 -> 0.94286765 | T31: 295 | U31: =(T31-H31)/T31 -> 0.93415254
E32: 花宙2.0 肯尼亚AB 6kg（自备） 云南3A 4kg（自备） 耶加G2 5kg (自备) 布谷2kg (自备) 花恬珀 3kg（自备） | F32: 200克 | G32: =(6*70+68*4+5*70+105*2+78*3)/20+8 -> 82.3 | H32: =G32*20/32 -> 51.4375 | I32: =ROUNDDOWN(J32*1.3,0) -> 162 | J32: 125 | K32: =(J32-H32)/J32 -> 0.5885 | L32: =I32*0.95 -> 153.9 | M32: =I32*0.72 -> 116.64 | N32: =I32*0.68 -> 110.16 | O32: =I32*0.64 -> 103.68 | P32: 95 | Q32: =(P32-H32)/P32 -> 0.45855263 | R32: 85 | S32: =(R32-H32)/R32 -> 0.39485294 | T32: 80 | U32: =(T32-H32)/T32 -> 0.35703125
E33: 充电桩 | F33: 200克 | H33: 25 | I33: =ROUNDDOWN(J33*1.3,0) -> 130 | J33: 100 | K33: =(J33-H33)/J33 -> 0.75 | L33: =I33*0.95 -> 123.5 | M33: =I33*0.72 -> 93.6 | N33: =I33*0.68 -> 88.4 | O33: =I33*0.64 -> 83.2 | P33: 52 | Q33: =(P33-H33)/P33 -> 0.51923077 | R33: 48 | S33: =(R33-H33)/R33 -> 0.47916667 | T33: 45 | U33: =(T33-H33)/T33 -> 0.44444444
E34: 1702二号 耶加2kg（自备），肯尼亚2.6kg（自备），曼特宁1.4kg（自备），布谷7kg（自备），摩卡G4 7kg | F34: 200克 | G34: =(70*2+2.6*70+1.4*73+7*105+7*65)/20+8 -> 88.71 | H34: =G34*20/32 -> 55.44375 | I34: =ROUNDDOWN(J34*1.3,0) -> 0 | K34: =(J34-H34)/J34 -> #DIV/0! | L34: =I34*0.95 -> 0 | M34: =I34*0.72 -> 0 | N34: =I34*0.68 -> 0 | O34: =I34*0.64 -> 0 | P34: 85 | Q34: =(P34-H34)/P34 -> 0.34772059 | R34: 75 | S34: =(R34-H34)/R34 -> 0.26075 | T34: 70 | U34: =(T34-H34)/T34 -> 0.20794643
F35: 200克 | I35: =ROUNDDOWN(J35*1.3,0) -> 0 | K35: =(J35-H35)/J35 -> #DIV/0! | L35: =I35*0.95 -> 0 | M35: =I35*0.72 -> 0 | N35: =I35*0.68 -> 0 | O35: =I35*0.64 -> 0 | P35: 385 | Q35: =(P35-H35)/P35 -> 1 | R35: 360 | S35: =(R35-H35)/R35 -> 1 | T35: x | U35: =(T35-H35)/T35 -> #VALUE!
F36: 200克 | I36: =ROUNDDOWN(J36*1.3,0) -> 0 | K36: =(J36-H36)/J36 -> #DIV/0! | L36: =I36*0.95 -> 0 | M36: =I36*0.72 -> 0 | N36: =I36*0.68 -> 0 | O36: =I36*0.64 -> 0 | P36: 375 | Q36: =(P36-H36)/P36 -> 1 | R36: x | S36: =(R36-H36)/R36 -> #VALUE! | T36: x | U36: =(T36-H36)/T36 -> #VALUE!
F37: 200克 | I37: =ROUNDDOWN(J37*1.3,0) -> 0 | K37: =(J37-H37)/J37 -> #DIV/0! | L37: =I37*0.95 -> 0 | M37: =I37*0.72 -> 0 | N37: =I37*0.68 -> 0 | O37: =I37*0.64 -> 0 | P37: 149 | Q37: =(P37-H37)/P37 -> 1 | R37: 139 | S37: =(R37-H37)/R37 -> 1 | T37: x | U37: =(T37-H37)/T37 -> #VALUE!
F38: 200克 | I38: =ROUNDDOWN(J38*1.3,0) -> 0 | K38: =(J38-H38)/J38 -> #DIV/0! | L38: =I38*0.95 -> 0 | M38: =I38*0.72 -> 0 | N38: =I38*0.68 -> 0 | O38: =I38*0.64 -> 0 | P38: 66 | Q38: =(P38-H38)/P38 -> 1 | R38: 60 | S38: =(R38-H38)/R38 -> 1 | T38: 55 | U38: =(T38-H38)/T38 -> 1
F39: 200克 | I39: =ROUNDDOWN(J39*1.3,0) -> 0 | K39: =(J39-H39)/J39 -> #DIV/0! | L39: =I39*0.95 -> 0 | M39: =I39*0.72 -> 0 | N39: =I39*0.68 -> 0 | O39: =I39*0.64 -> 0 | P39: 46 | Q39: =(P39-H39)/P39 -> 1 | R39: 40 | S39: =(R39-H39)/R39 -> 1 | T39: 36 | U39: =(T39-H39)/T39 -> 1
F40: 200克 | I40: =ROUNDDOWN(J40*1.3,0) -> 0 | K40: =(J40-H40)/J40 -> #DIV/0! | L40: =I40*0.95 -> 0 | M40: =I40*0.72 -> 0 | N40: =I40*0.68 -> 0 | O40: =I40*0.64 -> 0 | P40: 60 | Q40: =(P40-H40)/P40 -> 1 | R40: 55 | S40: =(R40-H40)/R40 -> 1 | T40: 50 | U40: =(T40-H40)/T40 -> 1
...

Sheet 生豆成本表
A1: 订购时间 | B1: 品名 | C1: 成本价 | D1: 订购数量 | E1: 供应商
A2: 45717 | B2: 耶加雪菲G2 | C2: 65 | E2: 石光
A3: 45629 | B3: 埃塞胡罗 | C3: 83 | E3: 集豆
A4: 45218 | B4: 乌拉嘎提波哈洛 | C4: 178 | E4: 啡常享
A5: 44719 | B5: 谷吉低因 | C5: 68 | E5: Royal
A6: 45315 | B6: 五号花园 | C6: 198 | E6: 集豆
A7: 45723 | B7: 肯尼亚奥克兰 | C7: 128 | E7: 啡常享
A8: 45693 | B8: 肯尼亚C | C8: 66 | E8: 石光
B9: 天堂92朗姆酒 | C9: 198 | E9: 香臣
B10: 拉斯拉哈斯H1 | C10: 168 | E10: 金粽
B11: 黄蜜薇拉萨奇 | C11: =5451/69 -> 79 | E11: 意可坊
B12: 哥斯达黎加贝多芬 | C12: 170 | E12: 金粽
B13: 翡翠绿标 艾薇罗 | C13: 780 | E13: 林果
B14: 90+埃莱塔瑰夏 | C14: 390 | E14: 金粽
B15: 分界线庄园希爪 | C15: =13580/35 -> 388 | E15: 际遇
B16: 天堂92条纹波旁 | C16: 273.5 | E16: 鲜农
B17: 分界线瑰夏 | C17: 238 | E17: 鲜农
B18: 蓝山康丘特 | C18: 550 | E18: 啡常享
B19: DR132 | C19: 95 | E19: 王鑫
B20: 花恬珀 | C20: =3840/60 -> 64 | E20: 秋珀
B21: 版纳紫妃 | C21: 72 | E21: 思东
B22: 咖威曼特宁G1 | C22: 71 | E22: 咖威
A23: 45655 | B23: Jet亚齐曼特宁 | C23: 78 | E23: 珈露梦
A24: 45719 | B24: 科布兰瑰夏 | C24: 268 | E24: 啡常享
A25: 45651 | B25: 虹光公主 | C25: 57 | E25: 芬咖
B26: 云南AAA | C26: 50 | E26: 林果
B27: 云南AA | C27: 52 | E27: 林果
B28: 重发酵云南 | C28: 32 | E28: 思东
B29: 洪都拉斯星空雪莉 | C29: 134 | E29: 咖威
B30: 洪都拉斯荔枝兰 | C30: 149 | E30: 咖威
B31: 黑洞 | C31: =50*0.3+52*0.4+65*0.2+69*0.1+6*0.8+8*0.2 -> 62.1
B32: 流星 | C32: =50*0.5+65*0.2+52*0.3+6 -> 59.6
B33: 天之语 | C33: =59*0.3+60*0.3+65*0.2+65*0.2+8 -> 69.7
B34: 花宙2.0 | C34: 80
A35: 45778 | B35: 花魁XS | C35: 146 | E35: 弘顺
A36: 45778 | B36: 肯尼亚莓宴 | C36: 128 | E36: 啡常享
A37: 45870 | B37: 肯尼亚AB | C37: 69 | E37: 石光
A38: 45958 | B38: 哥伦比亚分界线希爪 | C38: 252 | D38: 15 | E38: 鲜农
A39: 45953 | B39: 曼特宁禾纳斯 | C39: 88 | D39: 30 | E39: 石光
A40: 45953 | B40: 曼特宁G1 | C40: 73 | D40: 60 | E40: 石光
...

Sheet 价格体系
B1: 毛利率70%为基础 | E1: =50*1.5 -> 75 | H1: 运费 | I1: 3-10元
B2: 定价 | C2: 生豆成本X3.3 | E2: =50*2 -> 100 | H2: 包装 | I2: 1.5 | K2: =65*I4*3.3 -> 53.625 | M2: =65/800+2+5 -> 7.08125
B3: 淘宝一口价 | C3: 1.3 | E3: =50*2.5 -> 125 | H3: 运费 | I3: 3
E4: =50*3.3 -> 165 | H4: 200克系数 | I4: =200/800 -> 0.25 | K4: =144*0.25*3.3 -> 118.8
B5: 亲友 | C5: 0.85 | H5: 500克系数 | I5: =500/800 -> 0.625
A7: 单品 | B7: 商户基础优惠 | C7: 0.7 | D7: =95*0.7 -> 66.5 | H7: 生豆成本 | I7: 65 | K7: =(I7*I4+I2+I3)*3.3 -> 68.475
B8: 大箱优惠 | C8: 0.65 | D8: =100*0.75 -> 75
B9: 超大箱/分销1 | C9: 0.6 | D9: =68*0.7 -> 47.6 | H9: =40*3.3 -> 132
B10: 分销2 | C10: 0.5 | H10: =40*2.5 -> 100
B11: 分销3 | C11: 0.4 | K11: =65/800*200 -> 16.25
A13: 意式 | B13: 商户基础优惠 | C13: 0.7
B14: 大箱优惠 | C14: 0.65
B15: 超大箱/分销1 | C15: 0.6
B16: 分销2 | C16: 0.5
B17: 分销3 | C17: 0.4
K18: =40*3.3 -> 132

Sheet 豆单_零售（2507) 
B2: 订购前请先看以下说明 单品豆规格皆为200克装 配方型/意式豆皆为500克装 低单价咖啡通常会有常备库存，7天内烘焙的库存会直接出货 ＊下单后三工作日内烘焙发货（周末休息）
B3: ＊付款请支付下方三个公司户收款方式，不用个人微信收款~敬请见谅＊
B4: 折石咖啡 江承哲严选咖啡豆单
B5: 产区 | C5: 序号 | D5: 烘焙度 | E5: 规格 | F5: 香型 | G5: 果酸感 | H5: 简称 | I5: 咖啡/商品名称 | J5: 享味价
B6: 非洲 | C6: 1 | D6: 中浅焙 | E6: 200克 | F6: 清新 果香 | G6: ♤♤♤♤ | H6: 柠檬花 | I6: ☆★★（经典畅销）埃塞俄比亚耶加雪菲柠檬花 #清香柠檬花 #蜂蜜红茶 #轻焦糖 #甜酸明亮愉悦 | J6: 66
C7: 2 | D7: 中焙 | E7: 200克 | F7: 蜜香红茶 柑橘甜 | G7: ♤♤ | H7: 蜜香摩卡 | I7: 埃塞俄比亚耶加雪菲蜜香摩卡 #蜂蜜 #柑橘 #锡兰红茶 #淡花香 #甜美温和口感舒爽有厚度 | J7: 66
C8: 3 | D8: 深焙 | E8: 200克 | F8: 厚重 浓香 | G8: ♤ | H8: 黑美人 | I8: 埃塞俄比亚耶加雪菲摩卡黑美人（深烘焙精品咖啡的典范） #焦糖烤橘子 #可可 #豆蔻 #甘甜醇香 | J8: 66
C9: 4 | D9: 中浅焙 | E9: 200克 | F9: 花韵 果香 | G9: ♤♤♤♤ | H9: 阿拉卡 | I9: 埃塞俄比亚谷吉汉贝拉阿拉卡厌氧日晒G1 #红葡萄酒 #覆盆子 #油桃 #高甜感香气浓郁 | J9: 118
C10: 5 | D10: 中浅焙 | E10: 200克 | F10: 花韵 果香 | G10: ♤♤♤♤ | H10: 花魁XS | I10: 埃塞俄比亚谷吉汉贝拉正宗2025花魁XS限量版 #紫葡萄 #蓝莓 #草莓水果糖 #香水月季 #高甜丰厚的果汁感 | J10: 118
C11: 6 | D11: 中浅焙 | E11: 200克 | F11: 优雅 果香 | G11: ♤♤♤♤ | H11: 甜乐莓 | I11: 埃塞俄比亚西达摩日晒甜乐莓 #草莓 #白杏 #柑橘 #橙花 #红茶 #甜酸活泼，香气丰盛 | J11: 118
C12: 7 | D12: 中焙 | E12: 200克 | F12: 巧克力调性 | G12: ♤♤ | H12: 谷吉低因 | I12: 埃塞俄比亚谷吉日晒山水处理法真·低因咖啡 （无负担喝咖啡者的必备品） #焦糖巧克力 #橘皮 #红糖 #甜香温和，质地甘醇无负担 | J12: 66
C13: 8 | D13: 中浅焙 | E13: 200克 | F13: 莓果花香 | G13: ♤♤♤♤ | H13: 莓宴 | I13: 肯尼亚奇安布奥克兰庄园-莓宴（AA TOP规格） #黑莓 #蓝莓 #覆盆子 #苹果花 #血橙 #果汁感强，酸甜愉悦又饱满 | J13: 110
C14: 9 | D14: 中深焙 | E14: 200克 | F14: 醇甜厚实 巧克力浓香 | G14: ♤ | H14: 蜜可可 | I14: 肯尼亚尼耶利蜜可可Mielcoco（饱饱的厚甜感又顺滑哦） #巧克力 #锡兰红茶 #小白杏 #柴烧黑糖 顺滑厚实甜美 | J14: 75
B15: 中南美洲 | C15: 10 | D15: 中深焙 | E15: 200克 | F15: 多层次 果香酒韵 | G15: ♤♤ | H15: 天堂92朗姆酒 | I15: ★★★★★哥伦比亚考卡天堂92啤酒酵母+朗姆酒桶静置（焙度加深！更加厚重好喝） #黑朗姆酒 #焦糖巧克力 #啤酒花 #层次多元口感爽口厚重 | J15: 208
C16: 11 | D16: 中浅焙 | E16: 200克 | F16: 特色清酒香 | G16: ♤♤♤♤ | H16: 天堂92条纹波旁 | I16: 哥伦比亚考卡天堂92日本清酒曲厌氧水洗条纹波旁 #清酒 #粉色花香 #荔枝 #口感活泼余韵悠长 | J16: 368
C17: 12 | D17: 中浅焙 | E17: 200克 | F17: 高浓度多层次 莓果水果浓香 | G17: ♤♤♤♤ | H17: 分界线庄园希爪 | I17: ★★★★哥伦比亚分界线庄园双重发酵日晒希爪Sidra（好喝到炸裂！浓郁复合果汁） #复合莓果汁 #杏桃 #紫色水果 #紫色花香 #口感质地细腻饱满甜美 | J17: 358
C18: 13 | D18: 中焙 | E18: 200克 | F18: 蜜糖甜李花香 | G18: ♤♤ | H18: 分界线瑰夏 | I18: ★★★★哥伦比亚分界线庄园水洗瑰夏（名庄瑰夏，性价比高！） #蜂糖李 #槐花蜜 #鲜炒绿茶尾韵 #口感甜厚圆润愉悦 | J18: 240
C19: 14 | D19: 中深焙 | E19: 200克 | F19: 醇甜 坚果巧克力 | G19: ♤♤ | H19: 圣奥古斯丁 | I19: 哥伦比亚薇拉圣奥古斯丁SUPREMO #巧克力 #甜黑李 #红杏 #焦糖 #口感顺滑醇甜 | J19: 72
C20: 15 | D20: 中焙 | E20: 200克 | F20: 高雅 花果香 | G20: ♤♤♤♤ | H20: 贝多芬 | I20: 哥斯达黎加卡内特庄园音乐家系列-贝多芬酵素水洗 #柠檬 #葡萄干 #花香 #层次丰富甜酸如果汁迷人 | J20: 168
C21: 16 | D21: 中浅焙 | E21: 200克 | F21: 高雅 花果香 | G21: ♤♤♤♤ | H21: 翡翠绿标 艾薇罗 | I21: ★★★★★巴拿马波奎特翡翠庄园绿标水洗瑰夏艾薇罗地块(El Velo)2025 #香草玫瑰 #柠檬 #黑莓 #复合水果茶 #活泼多汁口感 | J21: 550
C22: 17 | D22: 中浅焙 | E22: 200克 | F22: 浓郁 果干爆香 | G22: ♤♤♤♤ | H22: 90+埃莱塔瑰夏 | I22: 巴拿马沃肯90+ Eleta埃莱塔瑰夏特殊处理法（高端品牌风味强度就是高） #蜜渍凤梨 #佛手柑 #柚子 #口感丰富酸甜活泼 | J22: 380
C23: 18 | D23: 中焙 | E23: 200克 | F23: 圆润 果香 | G23: ♤♤♤ | H23: 小甜心瑰夏 | I23: 秘鲁小甜心瑰夏 #红李 #红杏 #柑橘 #淡花香 #口感温和，温润平衡顺口 | J23: 128
C24: 19 | D24: 中焙 | E24: 200克 | F24: 圆润 果香 | G24: ♤♤ | H24: 蓝山 | I24: 牙买加康丘特庄园蓝山一号铁比卡（正宗蓝山中的优质货，送礼好选） #蜜糖杏李 #高质感巧克力 #甜榛子 #丝滑平衡无敌的口感 | J24: 480
B25: 亚洲 | C25: 20 | D25: 中焙 | E25: 200克 | F25: 高浓度多层次 莓果水果浓香 | G25: ♤♤ | H25: DR132 | I25: 西双版纳孟宋高海拔新品种DR132厌氧日晒(稀有!黄果皮变种卡蒂姆） #青芒 #生姜花 #肉豆蔻 #糖蜜与热带水果甜 | J25: 98
C26: 21 | D26: 中焙 | E26: 200克 | F26: 重酵 果香 | G26: ♤♤♤ | H26: 花恬珀 | I26: 云南临沧秋珀庄园浓果日晒-花恬珀 #车厘子 #红色莓果 #红色花香 #口感丰富多层次 | J26: 78
C27: 22 | D27: 中焙 | E27: 200克 | F27: 高雅 蜜甜核果香 | G27: ♤♤♤ | H27: 太阳鸟 | I27: 西双版纳西定云乐庄园高海拔水洗巴蒂安Batian太阳鸟 #蔓越莓 #柑橘 #玫瑰李 #高活泼酸甜醇厚咖啡 | J27: 168
C28: 23 | D28: 中深焙 | E28: 200克 | F28: 浓香 | G28: ♤♤ | H28: 日光曼特宁 | I28: ☆苏门答腊日光曼特宁(经典曼特宁的甜香风格) #森林气息 #焦糖 #坚果黑可可 | J28: 78
C29: 24 | D29: 中深焙 | E29: 200克 | F29: 浓香 | G29: ♤♤ | H29: 白金曼特宁 | I29: ★★苏门答腊迦幼山白金曼特宁水洗处理法（颗粒又大又长，十分漂亮） #仙草 #糖蜜 #黑巧克力 #黑李甜酸 #质感厚重却十足干净 | J29: 98
B30: 大洋洲 | C30: 25 | D30: 中浅焙 | E30: 200克 | F30: 高雅 花果香 | G30: ♤♤♤ | H30: 科布兰瑰夏 | I30: 巴布亚新几内亚巴罗伊达庄园科布兰水洗瑰夏 #玫瑰果 #红心猕猴桃 #树莓 #奶油草莓 #甜酸美味，果汁感十足 | J30: 228
B31: 折石 配方 咖啡 （意式） | C31: 26 | D31: 深焙 | E31: 500克 | F31: 威力 浓香 | G31: ♤ | H31: 黑洞 | I31: ☆★无负担配方设计 黑洞/500克装（经典产品，推荐咖啡店意式市使用首选） （孟连+普洱+哥伦比亚+西达摩） #厚重苦甜巧克力 #核果甜香 #重焦糖 #饱满却不苦涩，奶咖的绝配 | J31: 110
C32: 27 | D32: 中深焙 | E32: 500克 | F32: 圆润 坚果与果香 | G32: ♤♤ | H32: 流星 | I32: ☆★无负担配方设计 流星/500克装（经典产品，咖啡店首选）（孟连+普洱+西达摩） #锡兰红茶 #甜杏李 #坚果 #口感温润，轻盈柔顺不迟腻 | J32: 110
C33: 28 | D33: 中焙 | E33: 500克 | F33: 圆润 果香与甜香 | G33: ♤♤ | H33: 天之语 | I33: 细腻感配方设计 天之语 500克装（埃塞水洗&日晒+巴西+哥伦比亚） #红糖蜜 #烤橘香 #奶油巧克力 #柔顺干净追求平衡的典范口感 | J33: 120
C34: 29 | D34: 中浅焙 | E34: 500克 | F34: 多层次 花果香 | G34: ♤♤♤ | H34: 花宙2.0 | I34: ★★细腻感配方设计 花宙2.0甜美式配方（埃塞日晒+肯尼亚+哥伦比亚+耶加） #甜柑橘 #鲜红莓 #核果蜜香 #清爽上扬果汁感甜酸质地 | J34: 125
C35: 30 | D35: 深焙 | E35: 500克 | F35: 厚重 多层次浓香 | G35: ♤ | H35: 充电桩 | I35: ★★★★盲盒配方 充电桩/500克装（主基调一致 每批次细节不同，重口味者的心头好） #巧克力 #重焦糖 #朗姆威士忌 #入口丰富 #口感饱满尾韵层次 | J35: 110
B36: 折石定制 浓缩液 | C36: 31 | D36: 深焙 | E36: 30ml | F36: 威力 浓香 | G36: ♤ | H36: 黑洞浓缩液 散装 | I36: 黑洞浓缩液咖啡散装（单条30ml装，无外盒，每条可冲得180~240ml咖啡） #苦甜巧克力 #核果甜香 #黑糖 #饱满不苦涩，奶咖绝配 | J36: 5.5
C37: 32 | D37: 深焙 | E37: 20条 | F37: 威力 浓香 | G37: ♤ | H37: 黑洞浓缩液 20入盒装 | I37: 黑洞浓缩液咖啡20入盒装（透明盒装20条，每条可冲得180~240ml咖啡） #苦甜巧克力 #核果甜香 #黑糖 #饱满不苦涩，奶咖绝配 | J37: 98
B38: 以上商户合作优惠价与大量订购批发价含税不含运
H39: 扫描付款方式
B41: ★热门推荐
B42: ★★ 强力推荐
...

Sheet 豆单_批发（2507)
B2: 订购前请先看以下说明 单品豆规格皆为200克装，大量订购优惠的[200克]24包是针对单品豆的批发条件 意式豆皆为500克装，大量订购优惠的[500克]32包是针对意式豆的批发条件 咖啡豆需要满足单一品项的数量才能获得该品项的优惠价 ＊咖啡通常会有常备库存，7天内烘焙的库存会直接出货 ＊下单后三工作日内烘焙发货（周末休息） ＊ 商户合作优惠优惠无最低起订量，但您若能尽量单品豆以4包倍数订购，意式豆以2包500克为单位订购，我们将无比感谢您 ＊ 合作商户享大量订购优惠价，意式豆请按32包倍数订购，单品豆按24包倍数订购 ＊ 大量订购我们能够用上大机器烘焙，将省下来的时间回馈给您，有能力可以多订一些，更加优惠哦
B3: ＊付款请支付下方三个公司户收款方式，不用个人微信收款~敬请见谅＊
B4: 折石咖啡 江承哲严选咖啡豆单
B5: 产区 | C5: 序号 | D5: 烘焙度 | E5: 规格 | F5: 香型 | G5: 果酸感 | H5: 简称 | I5: 咖啡/商品名称 | J5: 享味价 | K5: 商户合作优惠 [200克]4包/件 [500克]2包/件 | L5: 大量订购优惠 [200克]24包 [500克]32包 | M5: 超大量优惠 [200克]60包 [500克]96包
B6: 非洲 | C6: 1 | D6: 中浅焙 | E6: 200克 | F6: 清新 果香 | G6: ♤♤♤♤ | H6: 柠檬花 | I6: ☆★★（经典畅销）埃塞俄比亚耶加雪菲柠檬花 #清香柠檬花 #蜂蜜红茶 #轻焦糖 #甜酸明亮愉悦 | J6: 66 | K6: 50 | L6: 46 | M6: 40
C7: 2 | D7: 中焙 | E7: 200克 | F7: 蜜香红茶 柑橘甜 | G7: ♤♤ | H7: 蜜香摩卡 | I7: 埃塞俄比亚耶加雪菲蜜香摩卡 #蜂蜜 #柑橘 #锡兰红茶 #淡花香 #甜美温和口感舒爽有厚度 | J7: 66 | K7: 50 | L7: 46 | M7: 40
C8: 3 | D8: 深焙 | E8: 200克 | F8: 厚重 浓香 | G8: ♤ | H8: 黑美人 | I8: 埃塞俄比亚耶加雪菲摩卡黑美人（深烘焙精品咖啡的典范） #焦糖烤橘子 #可可 #豆蔻 #甘甜醇香 | J8: 66 | K8: 50 | L8: 46 | M8: 40
C9: 4 | D9: 中浅焙 | E9: 200克 | F9: 花韵 果香 | G9: ♤♤♤♤ | H9: 阿拉卡 | I9: 埃塞俄比亚谷吉汉贝拉阿拉卡厌氧日晒G1 #红葡萄酒 #覆盆子 #油桃 #高甜感香气浓郁 | J9: 118 | K9: 88 | L9: 82 | M9: 72
C10: 5 | D10: 中浅焙 | E10: 200克 | F10: 花韵 果香 | G10: ♤♤♤♤ | H10: 花魁XS | I10: 埃塞俄比亚谷吉汉贝拉正宗2025花魁XS限量版 #紫葡萄 #蓝莓 #草莓水果糖 #香水月季 #高甜丰厚的果汁感 | J10: 118 | K10: 88 | L10: 82 | M10: 72
C11: 6 | D11: 中浅焙 | E11: 200克 | F11: 优雅 果香 | G11: ♤♤♤♤ | H11: 甜乐莓 | I11: 埃塞俄比亚西达摩日晒甜乐莓 #草莓 #白杏 #柑橘 #橙花 #红茶 #甜酸活泼，香气丰盛 | J11: 118 | K11: 88 | L11: 82 | M11: 72
C12: 7 | D12: 中焙 | E12: 200克 | F12: 巧克力调性 | G12: ♤♤ | H12: 谷吉低因 | I12: 埃塞俄比亚谷吉日晒山水处理法真·低因咖啡 （无负担喝咖啡者的必备品） #焦糖巧克力 #橘皮 #红糖 #甜香温和，质地甘醇无负担 | J12: 66 | K12: 50 | L12: 46 | M12: 40
C13: 8 | D13: 中浅焙 | E13: 200克 | F13: 莓果花香 | G13: ♤♤♤♤ | H13: 莓宴 | I13: 肯尼亚奇安布奥克兰庄园-莓宴（AA TOP规格） #黑莓 #蓝莓 #覆盆子 #苹果花 #血橙 #果汁感强，酸甜愉悦又饱满 | J13: 110 | K13: =J13*0.7 -> 77 | L13: 72 | M13: 66
C14: 9 | D14: 中深焙 | E14: 200克 | F14: 醇甜厚实 巧克力浓香 | G14: ♤ | H14: 蜜可可 | I14: 肯尼亚尼耶利蜜可可Mielcoco（饱饱的厚甜感又顺滑哦） #巧克力 #锡兰红茶 #小白杏 #柴烧黑糖 顺滑厚实甜美 | J14: 75 | K14: 55 | L14: 49 | M14: 45
B15: 中南美洲 | C15: 10 | D15: 中深焙 | E15: 200克 | F15: 多层次 果香酒韵 | G15: ♤♤ | H15: 天堂92朗姆酒 | I15: ★★★★★哥伦比亚考卡天堂92啤酒酵母+朗姆酒桶静置（焙度加深！更加厚重好喝） #黑朗姆酒 #焦糖巧克力 #啤酒花 #层次多元口感爽口厚重 | J15: 208 | K15: 156 | L15: 146 | M15: 135
C16: 11 | D16: 中浅焙 | E16: 200克 | F16: 特色清酒香 | G16: ♤♤♤♤ | H16: 天堂92条纹波旁 | I16: 哥伦比亚考卡天堂92日本清酒曲厌氧水洗条纹波旁 #清酒 #粉色花香 #荔枝 #口感活泼余韵悠长 | J16: 368 | K16: 298 | L16: 278.6 | M16: 239
C17: 12 | D17: 中浅焙 | E17: 200克 | F17: 高浓度多层次 莓果水果浓香 | G17: ♤♤♤♤ | H17: 分界线庄园希爪 | I17: ★★★★哥伦比亚分界线庄园双重发酵日晒希爪Sidra（好喝到炸裂！浓郁复合果汁） #复合莓果汁 #杏桃 #紫色水果 #紫色花香 #口感质地细腻饱满甜美 | J17: 358 | K17: 276 | L17: 257.6 | M17: 220
C18: 13 | D18: 中焙 | E18: 200克 | F18: 蜜糖甜李花香 | G18: ♤♤ | H18: 分界线瑰夏 | I18: ★★★★哥伦比亚分界线庄园水洗瑰夏（名庄瑰夏，性价比高！） #蜂糖李 #槐花蜜 #鲜炒绿茶尾韵 #口感甜厚圆润愉悦 | J18: 240 | K18: 180 | L18: 170 | M18: 160
C19: 14 | D19: 中深焙 | E19: 200克 | F19: 醇甜 坚果巧克力 | G19: ♤♤ | H19: 圣奥古斯丁 | I19: 哥伦比亚薇拉圣奥古斯丁SUPREMO #巧克力 #甜黑李 #红杏 #焦糖 #口感顺滑醇甜 | J19: 72 | K19: 52 | L19: 45 | M19: x
C20: 15 | D20: 中焙 | E20: 200克 | F20: 高雅 花果香 | G20: ♤♤♤♤ | H20: 贝多芬 | I20: 哥斯达黎加卡内特庄园音乐家系列-贝多芬酵素水洗 #柠檬 #葡萄干 #花香 #层次丰富甜酸如果汁迷人 | J20: 168 | K20: 98 | L20: x | M20: x
C21: 16 | D21: 中浅焙 | E21: 200克 | F21: 高雅 花果香 | G21: ♤♤♤♤ | H21: 翡翠绿标 艾薇罗 | I21: ★★★★★巴拿马波奎特翡翠庄园绿标水洗瑰夏艾薇罗地块(El Velo)2025 #香草玫瑰 #柠檬 #黑莓 #复合水果茶 #活泼多汁口感 | J21: 550 | K21: 480 | L21: 515 | M21: 500
C22: 17 | D22: 中浅焙 | E22: 200克 | F22: 浓郁 果干爆香 | G22: ♤♤♤♤ | H22: 90+埃莱塔瑰夏 | I22: 巴拿马沃肯90+ Eleta埃莱塔瑰夏特殊处理法（高端品牌风味强度就是高） #蜜渍凤梨 #佛手柑 #柚子 #口感丰富酸甜活泼 | J22: 380 | K22: 280 | L22: 340 | M22: 295
C23: 18 | D23: 中焙 | E23: 200克 | F23: 圆润 果香 | G23: ♤♤♤ | H23: 小甜心瑰夏 | I23: 秘鲁小甜心瑰夏 #红李 #红杏 #柑橘 #淡花香 #口感温和，温润平衡顺口 | J23: 128 | K23: 90 | L23: 83 | M23: 77
C24: 19 | D24: 中焙 | E24: 200克 | F24: 圆润 果香 | G24: ♤♤ | H24: 蓝山 | I24: 牙买加康丘特庄园蓝山一号铁比卡（正宗蓝山中的优质货，送礼好选） #蜜糖杏李 #高质感巧克力 #甜榛子 #丝滑平衡无敌的口感 | J24: 480 | K24: 398 | L24: 388 | M24: 330
B25: 亚洲 | C25: 20 | D25: 中焙 | E25: 200克 | F25: 高浓度多层次 莓果水果浓香 | G25: ♤♤ | H25: DR132 | I25: 西双版纳孟宋高海拔新品种DR132厌氧日晒(稀有!黄果皮变种卡蒂姆） #青芒 #生姜花 #肉豆蔻 #糖蜜与热带水果甜 | J25: 98 | K25: 75 | L25: 70 | M25: 65
C26: 21 | D26: 中焙 | E26: 200克 | F26: 重酵 果香 | G26: ♤♤♤ | H26: 花恬珀 | I26: 云南临沧秋珀庄园浓果日晒-花恬珀 #车厘子 #红色莓果 #红色花香 #口感丰富多层次 | J26: 78 | K26: 60 | L26: 55 | M26: 50
C27: 22 | D27: 中焙 | E27: 200克 | F27: 高雅 蜜甜核果香 | G27: ♤♤♤ | H27: 太阳鸟 | I27: 西双版纳西定云乐庄园高海拔水洗巴蒂安Batian太阳鸟 #蔓越莓 #柑橘 #玫瑰李 #高活泼酸甜醇厚咖啡 | J27: 168 | K27: 126 | L27: 118 | M27: 109
C28: 23 | D28: 中深焙 | E28: 200克 | F28: 浓香 | G28: ♤♤ | H28: 日光曼特宁 | I28: ☆苏门答腊日光曼特宁(经典曼特宁的甜香风格) #森林气息 #焦糖 #坚果黑可可 | J28: 78 | K28: 60 | L28: 55 | M28: 50
C29: 24 | D29: 中深焙 | E29: 200克 | F29: 浓香 | G29: ♤♤ | H29: 白金曼特宁 | I29: ★★苏门答腊迦幼山白金曼特宁水洗处理法（颗粒又大又长，十分漂亮） #仙草 #糖蜜 #黑巧克力 #黑李甜酸 #质感厚重却十足干净 | J29: 98 | K29: 75 | L29: 70 | M29: 65
B30: 大洋洲 | C30: 25 | D30: 中浅焙 | E30: 200克 | F30: 高雅 花果香 | G30: ♤♤♤ | H30: 科布兰瑰夏 | I30: 巴布亚新几内亚巴罗伊达庄园科布兰水洗瑰夏 #玫瑰果 #红心猕猴桃 #树莓 #奶油草莓 #甜酸美味，果汁感十足 | J30: 228 | K30: 160 | L30: 148 | M30: 137
B31: 折石 配方 咖啡 （意式） | C31: 26 | D31: 深焙 | E31: 500克 | F31: 威力 浓香 | G31: ♤ | H31: 黑洞 | I31: ☆★无负担配方设计 黑洞/500克装（经典产品，推荐咖啡店意式市使用首选） （孟连+普洱+哥伦比亚+西达摩） #厚重苦甜巧克力 #核果甜香 #重焦糖 #饱满却不苦涩，奶咖的绝配 | J31: 110 | K31: 80 | L31: 70 | M31: 65
C32: 27 | D32: 中深焙 | E32: 500克 | F32: 圆润 坚果与果香 | G32: ♤♤ | H32: 流星 | I32: ☆★无负担配方设计 流星/500克装（经典产品，咖啡店首选）（孟连+普洱+西达摩） #锡兰红茶 #甜杏李 #坚果 #口感温润，轻盈柔顺不迟腻 | J32: 110 | K32: 80 | L32: 70 | M32: 65
C33: 28 | D33: 中焙 | E33: 500克 | F33: 圆润 果香与甜香 | G33: ♤♤ | H33: 天之语 | I33: 细腻感配方设计 天之语 500克装（埃塞水洗&日晒+巴西+哥伦比亚） #红糖蜜 #烤橘香 #奶油巧克力 #柔顺干净追求平衡的典范口感 | J33: 120 | K33: 90 | L33: 80 | M33: 75
C34: 29 | D34: 中浅焙 | E34: 500克 | F34: 多层次 花果香 | G34: ♤♤♤ | H34: 花宙2.0 | I34: ★★细腻感配方设计 花宙2.0甜美式配方（埃塞日晒+肯尼亚+哥伦比亚+耶加） #甜柑橘 #鲜红莓 #核果蜜香 #清爽上扬果汁感甜酸质地 | J34: 125 | K34: 95 | L34: 85 | M34: 80
C35: 30 | D35: 深焙 | E35: 500克 | F35: 厚重 多层次浓香 | G35: ♤ | H35: 充电桩 | I35: ★★★★盲盒配方 充电桩/500克装（主基调一致 每批次细节不同，重口味者的心头好） #巧克力 #重焦糖 #朗姆威士忌 #入口丰富 #口感饱满尾韵层次 | J35: 110 | K35: 80 | L35: 70 | M35: 65
B36: 折石定制 浓缩液 | C36: 31 | D36: 深焙 | E36: 30ml | F36: 威力 浓香 | G36: ♤ | H36: 黑洞浓缩液 散装 | I36: 黑洞浓缩液咖啡散装（单条30ml装，无外盒，每条可冲得180~240ml咖啡） #苦甜巧克力 #核果甜香 #黑糖 #饱满不苦涩，奶咖绝配 | J36: 5.5 | K36: ￥3.5 任意数量 | L36: ￥3 100条起 | M36: ￥2.5 1000条起
C37: 32 | D37: 深焙 | E37: 20条 | F37: 威力 浓香 | G37: ♤ | H37: 黑洞浓缩液 20入盒装 | I37: 黑洞浓缩液咖啡20入盒装（透明盒装20条，每条可冲得180~240ml咖啡） #苦甜巧克力 #核果甜香 #黑糖 #饱满不苦涩，奶咖绝配 | J37: 98 | K37: ￥72 任意数量 | L37: ￥62 5盒起 | M37: ￥52 50盒起
B38: 以上商户合作优惠价与大量订购批发价含税不含运
H39: 扫描付款方式
B41: ★热门推荐
B42: ★★ 强力推荐
...

Sheet 生豆豆单（2503) 
B2: 订购前请先看以下说明 生豆订购最小单位1公斤 以下价格含税不含运费
B3: ＊付款请支付下方三个公司户收款方式，不用个人微信收款~敬请见谅＊
B4: 折石咖啡 江承哲严选咖啡豆单
B5: 产区 | C5: 序号 | D5: 简称 | E5: 咖啡/商品名称 | F5: 1kg | G5: 5kg起订 公斤价 | H5: 1箱|麻袋 公斤价
B6: 非洲 | C6: 1 | D6: 柠檬花 | E6: 埃塞俄比亚耶加雪菲G2 #清香柠檬花 #蜂蜜红茶 #轻焦糖 #甜酸明亮愉悦 | F6: 85 | G6: 80 | H6: 75
C7: 5 | D7: 花魁XS | E7: 埃塞俄比亚谷吉汉贝拉正宗2025花魁XS空运限量版 #紫葡萄 #蓝莓 #草莓水果糖 #香水月季 #高甜丰厚的果汁感 | F7: 162 | G7: 157 | H7: 152
C8: 6 | D8: 提波哈洛 | E8: ★★★埃塞俄比亚日晒乌拉嘎 提波哈洛 (74112品种，TOH得奖合作社，无法拒绝的划算) #热带水果 #葡萄酒香 #芒果 #精品巧克力 #口感甜酸愉悦多层次 | F8: 190 | G8: 185 | H8: x
C9: 7 | D9: 谷吉低因 | E9: 埃塞俄比亚谷吉日晒山水处理法真·低因咖啡 （无负担喝咖啡者的必备品） #焦糖巧克力 #橘皮 #红糖 #甜香温和，质地甘醇无负担 | F9: 80 | G9: 75 | H9: x
C10: 8 | D10: 五号花园 | E10: ★★★★埃塞俄比亚西达摩班莎阿劳咖啡74158-五号花园 （ COE冠军庄园ALO的新代表作） #草莓 #车厘子 #红苹果 #口感饱满顺滑甜美 | F10: 220 | G10: 215 | H10: x
C11: 9 | D11: 莓宴 | E11: 肯尼亚奇安布奥克兰庄园-莓宴（AA TOP规格） #黑莓 #蓝莓 #覆盆子 #苹果花 #血橙 #果汁感强，酸甜愉悦又饱满 | F11: 145 | G11: 140 | H11: 135
C12: 10 | D12: 蜜可可 | E12: 肯尼亚尼耶利蜜可可Mielcoco（饱饱的厚甜感又顺滑哦） #巧克力 #锡兰红茶 #小白杏 #柴烧黑糖 顺滑厚实甜美 | F12: 88 | G12: 83 | H12: 78
B13: 中南美洲 | C13: 11 | D13: 天堂92朗姆酒 | E13: ★★★★★哥伦比亚考卡天堂92啤酒酵母+朗姆酒桶静置（焙度加深！更加厚重好喝） #黑朗姆酒 #焦糖巧克力 #啤酒花 #层次多元口感爽口厚重 | F13: 215 | G13: 210 | H13: x
C14: 12 | D14: 拉斯拉哈斯H1 | E14: 哥斯达黎加拉斯拉哈斯H1(Centroamericano)慢速日晒（价格已调整，更优惠！） #紫葡萄 #白杏 #果汁感 #口感温润扎实甜润 | F14: 178 | G14: x | H14: x
C15: 13 | D15: 黄蜜薇拉萨奇 | E15: 哥斯达黎加中央谷底玫瑰庄园黄蜜薇拉萨奇 #黄糖 #综合坚果 #奶油巧克力 #口感温和顺口 | F15: 90 | G15: 85 | H15: x
C16: 15 | D16: 翡翠绿标 艾薇罗 | E16: ★★★★★巴拿马波奎特翡翠庄园绿标水洗瑰夏艾薇罗地块(El Velo)2024 #香草玫瑰 #柠檬 #黑莓 #复合水果茶 #活泼多汁口感 | F16: 790 | G16: x | H16: x
C17: 16 | D17: 90+埃莱塔瑰夏 | E17: 巴拿马沃肯90+ Eleta埃莱塔瑰夏特殊处理法（高端品牌风味强度就是高） #蜜渍凤梨 #佛手柑 #柚子 #口感丰富酸甜活泼 | F17: 410 | G17: 400 | H17: x
C18: 17 | D18: 分界线庄园希爪 | E18: ★★★★哥伦比亚分界线庄园双重发酵日晒希爪Sidra（好喝到炸裂！浓郁复合果汁） #复合莓果汁 #杏桃 #紫色水果 #紫色花香 #口感质地细腻饱满甜美 | F18: 405 | G18: 398 | H18: x
C19: 18 | D19: 天堂92条纹波旁 | E19: 哥伦比亚考卡天堂92日本清酒曲厌氧水洗条纹波旁 #清酒 #粉色花香 #荔枝 #口感活泼余韵悠长 | F19: 405 | G19: 398 | H19: x
C20: 19 | D20: 分界线瑰夏 | E20: ★★★★哥伦比亚分界线庄园水洗瑰夏（名庄瑰夏，性价比高！） #蜂糖李 #槐花蜜 #鲜炒绿茶尾韵 #口感甜厚圆润愉悦 | F20: 398 | G20: 200 | H20: 187
C21: 20 | D21: 蓝山 | E21: 牙买加康丘特庄园蓝山一号铁比卡（正宗蓝山中的优质货，送礼好选） #蜜糖杏李 #高质感巧克力 #甜榛子 #丝滑平衡无敌的口感 | F21: 275 | G21: 268 | H21: x
B22: 亚洲 | C22: 21 | D22: DR132 | E22: 西双版纳孟宋高海拔新品种DR132厌氧日晒(稀有!黄果皮变种卡蒂姆） #青芒 #生姜花 #肉豆蔻 #糖蜜与热带水果甜 | F22: 130 | G22: 125 | H22: x
C23: 22 | D23: 花恬珀 | E23: 云南临沧秋珀庄园浓果日晒-花恬珀 #车厘子 #红色莓果 #红色花香 #口感丰富多层次 | F23: 95 | G23: 90 | H23: 85
C24: 23 | D24: 版纳紫妃 | E24: ★★★云南西双版纳勐海西定高海拔紫叶变异种DR296精致水洗-版纳紫妃 （高质感必试） #淡雅花香 #油桃 #莓果 #蜂蜜 #口感丰富甜酸怡人 | F24: 100 | G24: 95 | H24: 90
C25: 24 | D25: 日光曼特宁 | E25: ☆苏门答腊日光曼特宁(经典曼特宁的甜香风格) #森林气息 #焦糖 #坚果黑可可 | F25: 90 | G25: 85 | H25: 80
C26: 25 | D26: 白金曼特宁 | E26: ★★苏门答腊迦幼山白金曼特宁水洗处理法（颗粒又大又长，十分漂亮） #仙草 #糖蜜 #黑巧克力 #黑李甜酸 #质感厚重却十足干净 | F26: 110 | G26: 105 | H26: 98
C27: 27 | D27: 云南普洱双A | E27: 云南普洱双A | F27: 78 | G27: 73 | H27: 68
C28: 28 | D28: 云南孟连三A | E28: 云南孟连AAA | F28: 85 | G28: 80 | H28: 75
B29: 大洋洲 | C29: 26 | D29: 科布兰瑰夏 | E29: 巴布亚新几内亚巴罗伊达庄园科布兰水洗瑰夏 #玫瑰果 #红心猕猴桃 #树莓 #奶油草莓 #甜酸美味，果汁感十足 | F29: 290 | G29: 285 | H29: 278
B30: 以上生豆价含税不含运费
E31: 扫描付款方式
B33: ★热门推荐
B34: ★★ 强力推荐
B36: 银行账户
B37: 银行账号：50131000396834475 户名：上海欧焙客贸易有限公司 开户行：上海农商银行桃浦支行
B40: 更新日期:2025/04/27

Sheet 淘宝产品信息更新状态
B2: 折石咖啡 江承哲严选咖啡豆单
B3: 产区 | C3: 序号 | D3: 烘焙度 | E3: 规格 | F3: 香型 | G3: 果酸感 | H3: 简称 | I3: 咖啡/商品名称 | J3: 享味价 | L3: 上架 | M3: 主图 | N3: 详情 | O3: 价格
B4: 非洲 | C4: 1 | D4: 中浅焙 | E4: 200克 | F4: 清新 果香 | G4: ♤♤♤♤ | H4: 柠檬花 | I4: ☆★★（经典畅销）埃塞俄比亚耶加雪菲柠檬花 #清香柠檬花 #蜂蜜红茶 #轻焦糖 #甜酸明亮愉悦 | J4: 66 | L4: o | M4: o | N4: x | O4: o
C5: 2 | D5: 中焙 | E5: 200克 | F5: 蜜香红茶 柑橘甜 | G5: ♤♤ | H5: 蜜香摩卡 | I5: 埃塞俄比亚耶加雪菲蜜香摩卡 #蜂蜜 #柑橘 #锡兰红茶 #淡花香 #甜美温和口感舒爽有厚度 | J5: 66 | L5: x | M5: x | N5: x | O5: x
C6: 3 | D6: 深焙 | E6: 200克 | F6: 厚重 浓香 | G6: ♤ | H6: 黑美人 | I6: 埃塞俄比亚耶加雪菲摩卡黑美人（深烘焙精品咖啡的典范） #焦糖烤橘子 #可可 #豆蔻 #甘甜醇香 | J6: 66 | L6: o | M6: x | N6: x | O6: x
C7: 4 | D7: 中浅焙 | E7: 200克 | F7: 花韵 果香 | G7: ♤♤♤♤ | H7: 蝴洛儿 | I7: 埃塞俄比亚南瑟波日晒74110 蝴洛儿（COE冠军ALO出品，品质保证） #酿黄梅 #红醋栗 #树莓 #口感顺滑低酸甜感丰沛 | J7: 98 | L7: o | M7: o | N7: x | O7: o
C8: 5 | D8: 中浅焙 | E8: 200克 | F8: 花韵 果香 | G8: ♤♤♤♤ | H8: 花魁XS | I8: 埃塞俄比亚谷吉汉贝拉正宗2025花魁XS空运限量版 #紫葡萄 #蓝莓 #草莓水果糖 #香水月季 #高甜丰厚的果汁感 | J8: 118 | L8: x | M8: x | N8: x | O8: x
C9: 6 | D9: 中浅焙 | E9: 200克 | F9: 优雅 果香 | G9: ♤♤♤♤ | H9: 提波哈洛 | I9: ★★★埃塞俄比亚日晒乌拉嘎 提波哈洛 (74112品种，TOH得奖合作社，无法拒绝的划算) #热带水果 #葡萄酒香 #芒果 #精品巧克力 #口感甜酸愉悦多层次 | J9: 178 | L9: o | M9: x
C10: 7 | D10: 中焙 | E10: 200克 | F10: 巧克力调性 | G10: ♤♤ | H10: 谷吉低因 | I10: 埃塞俄比亚谷吉日晒山水处理法真·低因咖啡 （无负担喝咖啡者的必备品） #焦糖巧克力 #橘皮 #红糖 #甜香温和，质地甘醇无负担 | J10: 66 | L10: o
C11: 8 | D11: 中浅焙 | E11: 200克 | F11: 甜美 浓香 | G11: ♤♤ | H11: 五号花园 | I11: ★★★★埃塞俄比亚西达摩班莎阿劳咖啡74158-五号花园 （ COE冠军庄园ALO的新代表作） #草莓 #车厘子 #红苹果 #口感饱满顺滑甜美 | J11: 219 | L11: o | M11: x
C12: 9 | D12: 中浅焙 | E12: 200克 | F12: 莓果花香 | G12: ♤♤♤♤ | H12: 莓宴 | I12: 肯尼亚奇安布奥克兰庄园-莓宴（AA TOP规格） #黑莓 #蓝莓 #覆盆子 #苹果花 #血橙 #果汁感强，酸甜愉悦又饱满 | J12: 110 | L12: o | M12: x
C13: 10 | D13: 中深焙 | E13: 200克 | F13: 醇甜厚实 巧克力浓香 | G13: ♤ | H13: 蜜可可 | I13: 肯尼亚尼耶利蜜可可Mielcoco（饱饱的厚甜感又顺滑哦） #巧克力 #锡兰红茶 #小白杏 #柴烧黑糖 顺滑厚实甜美 | J13: 66 | L13: o | M13: x | N13: x
B14: 中南美洲 | C14: 11 | D14: 中深焙 | E14: 200克 | F14: 多层次 果香酒韵 | G14: ♤♤ | H14: 天堂92朗姆酒 | I14: ★★★★★哥伦比亚考卡天堂92啤酒酵母+朗姆酒桶静置（焙度加深！更加厚重好喝） #黑朗姆酒 #焦糖巧克力 #啤酒花 #层次多元口感爽口厚重 | J14: 208 | L14: o | M14: x
C15: 12 | D15: 中焙 | E15: 200克 | F15: 高雅 花果香 | G15: ♤♤♤♤ | H15: 拉斯拉哈斯H1 | I15: 哥斯达黎加拉斯拉哈斯H1(Centroamericano)慢速日晒（价格已调整，更优惠！） #紫葡萄 #白杏 #果汁感 #口感温润扎实甜润 | J15: 145 | L15: o | M15: x
C16: 13 | D16: 中深焙 | E16: 200克 | F16: 醇甜 坚果巧克力 | G16: ♤♤ | H16: 黄蜜薇拉萨奇 | I16: 哥斯达黎加中央谷底玫瑰庄园黄蜜薇拉萨奇 #黄糖 #综合坚果 #奶油巧克力 #口感温和顺口 | J16: 72 | L16: x
C17: 14 | D17: 中焙 | E17: 200克 | F17: 高雅 花果香 | G17: ♤♤♤♤ | H17: 贝多芬 | I17: 哥斯达黎加卡内特庄园音乐家系列-贝多芬酵素水洗 #柠檬 #葡萄干 #花香 #层次丰富甜酸如果汁迷人 | J17: 168 | L17: o | M17: x
C18: 15 | D18: 中浅焙 | E18: 200克 | F18: 高雅 花果香 | G18: ♤♤♤♤ | H18: 翡翠绿标 艾薇罗 | I18: ★★★★★巴拿马波奎特翡翠庄园绿标水洗瑰夏艾薇罗地块(El Velo)2024 #香草玫瑰 #柠檬 #黑莓 #复合水果茶 #活泼多汁口感 | J18: 750 | L18: o | M18: x
C19: 16 | D19: 中浅焙 | E19: 200克 | F19: 浓郁 果干爆香 | G19: ♤♤♤♤ | H19: 90+埃莱塔瑰夏 | I19: 巴拿马沃肯90+ Eleta埃莱塔瑰夏特殊处理法（高端品牌风味强度就是高） #蜜渍凤梨 #佛手柑 #柚子 #口感丰富酸甜活泼 | J19: 490 | L19: o | M19: x
C20: 17 | D20: 中浅焙 | E20: 200克 | F20: 高浓度多层次 莓果水果浓香 | G20: ♤♤♤♤ | H20: 分界线庄园希爪 | I20: ★★★★哥伦比亚分界线庄园双重发酵日晒希爪Sidra（好喝到炸裂！浓郁复合果汁） #复合莓果汁 #杏桃 #紫色水果 #紫色花香 #口感质地细腻饱满甜美 | J20: 358 | L20: o | M20: o | N20: o | O20: o
C21: 18 | D21: 中浅焙 | E21: 200克 | F21: 特色清酒香 | G21: ♤♤♤♤ | H21: 天堂92条纹波旁 | I21: 哥伦比亚考卡天堂92日本清酒曲厌氧水洗条纹波旁 #清酒 #粉色花香 #荔枝 #口感活泼余韵悠长 | J21: 368 | L21: o | M21: o | N21: o | O21: o
C22: 19 | D22: 中焙 | E22: 200克 | F22: 蜜糖甜李花香 | G22: ♤♤ | H22: 分界线瑰夏 | I22: ★★★★哥伦比亚分界线庄园水洗瑰夏（名庄瑰夏，性价比高！） #蜂糖李 #槐花蜜 #鲜炒绿茶尾韵 #口感甜厚圆润愉悦 | J22: 398 | L22: o | M22: x | N22: x | O22: x
C23: 20 | D23: 中焙 | E23: 200克 | F23: 圆润 果香 | G23: ♤♤ | H23: 蓝山 | I23: 牙买加康丘特庄园蓝山一号铁比卡（正宗蓝山中的优质货，送礼好选） #蜜糖杏李 #高质感巧克力 #甜榛子 #丝滑平衡无敌的口感 | J23: 480 | L23: x | M23: x | N23: x | O23: x
B24: 亚洲 | C24: 21 | D24: 中焙 | E24: 200克 | F24: 高浓度多层次 莓果水果浓香 | G24: ♤♤ | H24: DR132 | I24: 西双版纳孟宋高海拔新品种DR132厌氧日晒(稀有!黄果皮变种卡蒂姆） #青芒 #生姜花 #肉豆蔻 #糖蜜与热带水果甜 | J24: 98 | L24: o | M24: o
C25: 22 | D25: 中焙 | E25: 200克 | F25: 重酵 果香 | G25: ♤♤♤ | H25: 花恬珀 | I25: 云南临沧秋珀庄园浓果日晒-花恬珀 #车厘子 #红色莓果 #红色花香 #口感丰富多层次 | J25: 78 | L25: o | M25: x
C26: 23 | D26: 中焙 | E26: 200克 | F26: 高雅 蜜甜核果香 | G26: ♤♤♤ | H26: 版纳紫妃 | I26: ★★★云南西双版纳勐海西定高海拔紫叶变异种DR296精致水洗-版纳紫妃 （高质感必试） #淡雅花香 #油桃 #莓果 #蜂蜜 #口感丰富甜酸怡人 | J26: 75 | L26: o | M26: 主图
C27: 24 | D27: 中深焙 | E27: 200克 | F27: 浓香 | G27: ♤♤ | H27: 日光曼特宁 | I27: ☆苏门答腊日光曼特宁(经典曼特宁的甜香风格) #森林气息 #焦糖 #坚果黑可可 | J27: 69 | L27: o | M27: x
